Workbook

Sheet 控制台
A1: 财务管理工作簿
A2: 选择公司和月份后点击刷新；金额默认人民币元。
A4: 公司编号
A5: 月份
A6: 数据状态 | B6: =IF(OR(B4="",B5=""),"请填写公司编号和月份",IF(AND(B4='刷新信息'!B6,B5='刷新信息'!B8),"当前选择与数据一致","选择已变化，请刷新"))
A7: 刷新结果 | B7: 尚未读取数据
A8: 最近刷新（UTC）
A11: 工作表 | B11: 用途
A12: 经营统计 | B12: 利润、现金收支、月度趋势
A13: 预算输入 / 预算对比 | B13: 按公司、月份、利润项目录入预算
A14: 账龄输入 / 账龄统计 | B14: 补充未核销单据；余额差额单列
A15: 出纳账 | B15: 总账现金及银行凭证明细
A16: 刷新信息 | B16: 数据身份、更新时间及原系统校验字段
A17: 使用说明 | B17: 一次性安装与口径说明
A20: 首次使用：在 Windows 运行安装脚本生成带刷新按钮的 .xlsm 文件。
A22: 黄色区域为人工输入；刷新不会覆盖预算和账龄输入。

Sheet 经营统计
A1: 经营统计
A2: 仅在选择与已刷新数据一致时显示；收支采用总账口径。
A4: 指标 | B4: 金额（元）
A5: 营业收入 | B5: =IF(AND('控制台'!B4<>"",'控制台'!B5<>"",'控制台'!B4='刷新信息'!B6,'控制台'!B5='刷新信息'!B8),SUMIFS('利润表'!C5:C200,'利润表'!F5:F200,"营业收入"),"")
A6: 营业成本 | B6: =IF(AND('控制台'!B4<>"",'控制台'!B5<>"",'控制台'!B4='刷新信息'!B6,'控制台'!B5='刷新信息'!B8),SUMIFS('利润表'!C5:C200,'利润表'!F5:F200,"营业成本"),"")
A7: 净利润 | B7: =IF(AND('控制台'!B4<>"",'控制台'!B5<>"",'控制台'!B4='刷新信息'!B6,'控制台'!B5='刷新信息'!B8),SUMIFS('利润表'!C5:C200,'利润表'!F5:F200,"净利润"),"")
A8: 现金银行流入 | B8: =IF(AND('控制台'!B4<>"",'控制台'!B5<>"",'控制台'!B4='刷新信息'!B6,'控制台'!B5='刷新信息'!B8),SUMIFS('出纳账'!I5:I6000,'出纳账'!M5:M6000,"<>内部划转"),"")
A9: 现金银行流出 | B9: =IF(AND('控制台'!B4<>"",'控制台'!B5<>"",'控制台'!B4='刷新信息'!B6,'控制台'!B5='刷新信息'!B8),SUMIFS('出纳账'!J5:J6000,'出纳账'!M5:M6000,"<>内部划转"),"")
A10: 现金银行净流入 | B10: =IF(AND('控制台'!B4<>"",'控制台'!B5<>"",'控制台'!B4='刷新信息'!B6,'控制台'!B5='刷新信息'!B8),B8-B9,"")
A11: 应收账款净额 | B11: =IF(AND('控制台'!B4<>"",'控制台'!B5<>"",'控制台'!B4='刷新信息'!B6,'控制台'!B5='刷新信息'!B8),SUMIFS('往来余额'!I5:I6000,'往来余额'!A5:A6000,"应收")-SUMIFS('往来余额'!J5:J6000,'往来余额'!A5:A6000,"应收"),"")
A12: 应付账款净额 | B12: =IF(AND('控制台'!B4<>"",'控制台'!B5<>"",'控制台'!B4='刷新信息'!B6,'控制台'!B5='刷新信息'!B8),SUMIFS('往来余额'!J5:J6000,'往来余额'!A5:A6000,"应付")-SUMIFS('往来余额'!I5:I6000,'往来余额'!A5:A6000,"应付"),"")
A15: 月份 | B15: 营业收入 | C15: 营业成本 | D15: 净利润
A16: =IF('控制台'!B5="","",LEFT('控制台'!B5,4)&"-01") | B16: =IF(AND(AND('控制台'!B4<>"",'控制台'!B5<>"",'控制台'!B4='刷新信息'!B6,'控制台'!B5='刷新信息'!B8),COUNTIF('月度趋势'!A5:A1000,A16)>0),SUMIFS('月度趋势'!D5:D1000,'月度趋势'!A5:A1000,A16,'月度趋势'!E5:E1000,"营业收入"),"") | C16: =IF(AND(AND('控制台'!B4<>"",'控制台'!B5<>"",'控制台'!B4='刷新信息'!B6,'控制台'!B5='刷新信息'!B8),COUNTIF('月度趋势'!A5:A1000,A16)>0),SUMIFS('月度趋势'!D5:D1000,'月度趋势'!A5:A1000,A16,'月度趋势'!E5:E1000,"营业成本"),"") | D16: =IF(AND(AND('控制台'!B4<>"",'控制台'!B5<>"",'控制台'!B4='刷新信息'!B6,'控制台'!B5='刷新信息'!B8),COUNTIF('月度趋势'!A5:A1000,A16)>0),SUMIFS('月度趋势'!D5:D1000,'月度趋势'!A5:A1000,A16,'月度趋势'!E5:E1000,"净利润"),"")
A17: =IF('控制台'!B5="","",LEFT('控制台'!B5,4)&"-02") | B17: =IF(AND(AND('控制台'!B4<>"",'控制台'!B5<>"",'控制台'!B4='刷新信息'!B6,'控制台'!B5='刷新信息'!B8),COUNTIF('月度趋势'!A5:A1000,A17)>0),SUMIFS('月度趋势'!D5:D1000,'月度趋势'!A5:A1000,A17,'月度趋势'!E5:E1000,"营业收入"),"") | C17: =IF(AND(AND('控制台'!B4<>"",'控制台'!B5<>"",'控制台'!B4='刷新信息'!B6,'控制台'!B5='刷新信息'!B8),COUNTIF('月度趋势'!A5:A1000,A17)>0),SUMIFS('月度趋势'!D5:D1000,'月度趋势'!A5:A1000,A17,'月度趋势'!E5:E1000,"营业成本"),"") | D17: =IF(AND(AND('控制台'!B4<>"",'控制台'!B5<>"",'控制台'!B4='刷新信息'!B6,'控制台'!B5='刷新信息'!B8),COUNTIF('月度趋势'!A5:A1000,A17)>0),SUMIFS('月度趋势'!D5:D1000,'月度趋势'!A5:A1000,A17,'月度趋势'!E5:E1000,"净利润"),"")
A18: =IF('控制台'!B5="","",LEFT('控制台'!B5,4)&"-03") | B18: =IF(AND(AND('控制台'!B4<>"",'控制台'!B5<>"",'控制台'!B4='刷新信息'!B6,'控制台'!B5='刷新信息'!B8),COUNTIF('月度趋势'!A5:A1000,A18)>0),SUMIFS('月度趋势'!D5:D1000,'月度趋势'!A5:A1000,A18,'月度趋势'!E5:E1000,"营业收入"),"") | C18: =IF(AND(AND('控制台'!B4<>"",'控制台'!B5<>"",'控制台'!B4='刷新信息'!B6,'控制台'!B5='刷新信息'!B8),COUNTIF('月度趋势'!A5:A1000,A18)>0),SUMIFS('月度趋势'!D5:D1000,'月度趋势'!A5:A1000,A18,'月度趋势'!E5:E1000,"营业成本"),"") | D18: =IF(AND(AND('控制台'!B4<>"",'控制台'!B5<>"",'控制台'!B4='刷新信息'!B6,'控制台'!B5='刷新信息'!B8),COUNTIF('月度趋势'!A5:A1000,A18)>0),SUMIFS('月度趋势'!D5:D1000,'月度趋势'!A5:A1000,A18,'月度趋势'!E5:E1000,"净利润"),"")
A19: =IF('控制台'!B5="","",LEFT('控制台'!B5,4)&"-04") | B19: =IF(AND(AND('控制台'!B4<>"",'控制台'!B5<>"",'控制台'!B4='刷新信息'!B6,'控制台'!B5='刷新信息'!B8),COUNTIF('月度趋势'!A5:A1000,A19)>0),SUMIFS('月度趋势'!D5:D1000,'月度趋势'!A5:A1000,A19,'月度趋势'!E5:E1000,"营业收入"),"") | C19: =IF(AND(AND('控制台'!B4<>"",'控制台'!B5<>"",'控制台'!B4='刷新信息'!B6,'控制台'!B5='刷新信息'!B8),COUNTIF('月度趋势'!A5:A1000,A19)>0),SUMIFS('月度趋势'!D5:D1000,'月度趋势'!A5:A1000,A19,'月度趋势'!E5:E1000,"营业成本"),"") | D19: =IF(AND(AND('控制台'!B4<>"",'控制台'!B5<>"",'控制台'!B4='刷新信息'!B6,'控制台'!B5='刷新信息'!B8),COUNTIF('月度趋势'!A5:A1000,A19)>0),SUMIFS('月度趋势'!D5:D1000,'月度趋势'!A5:A1000,A19,'月度趋势'!E5:E1000,"净利润"),"")
A20: =IF('控制台'!B5="","",LEFT('控制台'!B5,4)&"-05") | B20: =IF(AND(AND('控制台'!B4<>"",'控制台'!B5<>"",'控制台'!B4='刷新信息'!B6,'控制台'!B5='刷新信息'!B8),COUNTIF('月度趋势'!A5:A1000,A20)>0),SUMIFS('月度趋势'!D5:D1000,'月度趋势'!A5:A1000,A20,'月度趋势'!E5:E1000,"营业收入"),"") | C20: =IF(AND(AND('控制台'!B4<>"",'控制台'!B5<>"",'控制台'!B4='刷新信息'!B6,'控制台'!B5='刷新信息'!B8),COUNTIF('月度趋势'!A5:A1000,A20)>0),SUMIFS('月度趋势'!D5:D1000,'月度趋势'!A5:A1000,A20,'月度趋势'!E5:E1000,"营业成本"),"") | D20: =IF(AND(AND('控制台'!B4<>"",'控制台'!B5<>"",'控制台'!B4='刷新信息'!B6,'控制台'!B5='刷新信息'!B8),COUNTIF('月度趋势'!A5:A1000,A20)>0),SUMIFS('月度趋势'!D5:D1000,'月度趋势'!A5:A1000,A20,'月度趋势'!E5:E1000,"净利润"),"")
A21: =IF('控制台'!B5="","",LEFT('控制台'!B5,4)&"-06") | B21: =IF(AND(AND('控制台'!B4<>"",'控制台'!B5<>"",'控制台'!B4='刷新信息'!B6,'控制台'!B5='刷新信息'!B8),COUNTIF('月度趋势'!A5:A1000,A21)>0),SUMIFS('月度趋势'!D5:D1000,'月度趋势'!A5:A1000,A21,'月度趋势'!E5:E1000,"营业收入"),"") | C21: =IF(AND(AND('控制台'!B4<>"",'控制台'!B5<>"",'控制台'!B4='刷新信息'!B6,'控制台'!B5='刷新信息'!B8),COUNTIF('月度趋势'!A5:A1000,A21)>0),SUMIFS('月度趋势'!D5:D1000,'月度趋势'!A5:A1000,A21,'月度趋势'!E5:E1000,"营业成本"),"") | D21: =IF(AND(AND('控制台'!B4<>"",'控制台'!B5<>"",'控制台'!B4='刷新信息'!B6,'控制台'!B5='刷新信息'!B8),COUNTIF('月度趋势'!A5:A1000,A21)>0),SUMIFS('月度趋势'!D5:D1000,'月度趋势'!A5:A1000,A21,'月度趋势'!E5:E1000,"净利润"),"")
A22: =IF('控制台'!B5="","",LEFT('控制台'!B5,4)&"-07") | B22: =IF(AND(AND('控制台'!B4<>"",'控制台'!B5<>"",'控制台'!B4='刷新信息'!B6,'控制台'!B5='刷新信息'!B8),COUNTIF('月度趋势'!A5:A1000,A22)>0),SUMIFS('月度趋势'!D5:D1000,'月度趋势'!A5:A1000,A22,'月度趋势'!E5:E1000,"营业收入"),"") | C22: =IF(AND(AND('控制台'!B4<>"",'控制台'!B5<>"",'控制台'!B4='刷新信息'!B6,'控制台'!B5='刷新信息'!B8),COUNTIF('月度趋势'!A5:A1000,A22)>0),SUMIFS('月度趋势'!D5:D1000,'月度趋势'!A5:A1000,A22,'月度趋势'!E5:E1000,"营业成本"),"") | D22: =IF(AND(AND('控制台'!B4<>"",'控制台'!B5<>"",'控制台'!B4='刷新信息'!B6,'控制台'!B5='刷新信息'!B8),COUNTIF('月度趋势'!A5:A1000,A22)>0),SUMIFS('月度趋势'!D5:D1000,'月度趋势'!A5:A1000,A22,'月度趋势'!E5:E1000,"净利润"),"")
A23: =IF('控制台'!B5="","",LEFT('控制台'!B5,4)&"-08") | B23: =IF(AND(AND('控制台'!B4<>"",'控制台'!B5<>"",'控制台'!B4='刷新信息'!B6,'控制台'!B5='刷新信息'!B8),COUNTIF('月度趋势'!A5:A1000,A23)>0),SUMIFS('月度趋势'!D5:D1000,'月度趋势'!A5:A1000,A23,'月度趋势'!E5:E1000,"营业收入"),"") | C23: =IF(AND(AND('控制台'!B4<>"",'控制台'!B5<>"",'控制台'!B4='刷新信息'!B6,'控制台'!B5='刷新信息'!B8),COUNTIF('月度趋势'!A5:A1000,A23)>0),SUMIFS('月度趋势'!D5:D1000,'月度趋势'!A5:A1000,A23,'月度趋势'!E5:E1000,"营业成本"),"") | D23: =IF(AND(AND('控制台'!B4<>"",'控制台'!B5<>"",'控制台'!B4='刷新信息'!B6,'控制台'!B5='刷新信息'!B8),COUNTIF('月度趋势'!A5:A1000,A23)>0),SUMIFS('月度趋势'!D5:D1000,'月度趋势'!A5:A1000,A23,'月度趋势'!E5:E1000,"净利润"),"")
A24: =IF('控制台'!B5="","",LEFT('控制台'!B5,4)&"-09") | B24: =IF(AND(AND('控制台'!B4<>"",'控制台'!B5<>"",'控制台'!B4='刷新信息'!B6,'控制台'!B5='刷新信息'!B8),COUNTIF('月度趋势'!A5:A1000,A24)>0),SUMIFS('月度趋势'!D5:D1000,'月度趋势'!A5:A1000,A24,'月度趋势'!E5:E1000,"营业收入"),"") | C24: =IF(AND(AND('控制台'!B4<>"",'控制台'!B5<>"",'控制台'!B4='刷新信息'!B6,'控制台'!B5='刷新信息'!B8),COUNTIF('月度趋势'!A5:A1000,A24)>0),SUMIFS('月度趋势'!D5:D1000,'月度趋势'!A5:A1000,A24,'月度趋势'!E5:E1000,"营业成本"),"") | D24: =IF(AND(AND('控制台'!B4<>"",'控制台'!B5<>"",'控制台'!B4='刷新信息'!B6,'控制台'!B5='刷新信息'!B8),COUNTIF('月度趋势'!A5:A1000,A24)>0),SUMIFS('月度趋势'!D5:D1000,'月度趋势'!A5:A1000,A24,'月度趋势'!E5:E1000,"净利润"),"")
A25: =IF('控制台'!B5="","",LEFT('控制台'!B5,4)&"-10") | B25: =IF(AND(AND('控制台'!B4<>"",'控制台'!B5<>"",'控制台'!B4='刷新信息'!B6,'控制台'!B5='刷新信息'!B8),COUNTIF('月度趋势'!A5:A1000,A25)>0),SUMIFS('月度趋势'!D5:D1000,'月度趋势'!A5:A1000,A25,'月度趋势'!E5:E1000,"营业收入"),"") | C25: =IF(AND(AND('控制台'!B4<>"",'控制台'!B5<>"",'控制台'!B4='刷新信息'!B6,'控制台'!B5='刷新信息'!B8),COUNTIF('月度趋势'!A5:A1000,A25)>0),SUMIFS('月度趋势'!D5:D1000,'月度趋势'!A5:A1000,A25,'月度趋势'!E5:E1000,"营业成本"),"") | D25: =IF(AND(AND('控制台'!B4<>"",'控制台'!B5<>"",'控制台'!B4='刷新信息'!B6,'控制台'!B5='刷新信息'!B8),COUNTIF('月度趋势'!A5:A1000,A25)>0),SUMIFS('月度趋势'!D5:D1000,'月度趋势'!A5:A1000,A25,'月度趋势'!E5:E1000,"净利润"),"")
A26: =IF('控制台'!B5="","",LEFT('控制台'!B5,4)&"-11") | B26: =IF(AND(AND('控制台'!B4<>"",'控制台'!B5<>"",'控制台'!B4='刷新信息'!B6,'控制台'!B5='刷新信息'!B8),COUNTIF('月度趋势'!A5:A1000,A26)>0),SUMIFS('月度趋势'!D5:D1000,'月度趋势'!A5:A1000,A26,'月度趋势'!E5:E1000,"营业收入"),"") | C26: =IF(AND(AND('控制台'!B4<>"",'控制台'!B5<>"",'控制台'!B4='刷新信息'!B6,'控制台'!B5='刷新信息'!B8),COUNTIF('月度趋势'!A5:A1000,A26)>0),SUMIFS('月度趋势'!D5:D1000,'月度趋势'!A5:A1000,A26,'月度趋势'!E5:E1000,"营业成本"),"") | D26: =IF(AND(AND('控制台'!B4<>"",'控制台'!B5<>"",'控制台'!B4='刷新信息'!B6,'控制台'!B5='刷新信息'!B8),COUNTIF('月度趋势'!A5:A1000,A26)>0),SUMIFS('月度趋势'!D5:D1000,'月度趋势'!A5:A1000,A26,'月度趋势'!E5:E1000,"净利润"),"")
A27: =IF('控制台'!B5="","",LEFT('控制台'!B5,4)&"-12") | B27: =IF(AND(AND('控制台'!B4<>"",'控制台'!B5<>"",'控制台'!B4='刷新信息'!B6,'控制台'!B5='刷新信息'!B8),COUNTIF('月度趋势'!A5:A1000,A27)>0),SUMIFS('月度趋势'!D5:D1000,'月度趋势'!A5:A1000,A27,'月度趋势'!E5:E1000,"营业收入"),"") | C27: =IF(AND(AND('控制台'!B4<>"",'控制台'!B5<>"",'控制台'!B4='刷新信息'!B6,'控制台'!B5='刷新信息'!B8),COUNTIF('月度趋势'!A5:A1000,A27)>0),SUMIFS('月度趋势'!D5:D1000,'月度趋势'!A5:A1000,A27,'月度趋势'!E5:E1000,"营业成本"),"") | D27: =IF(AND(AND('控制台'!B4<>"",'控制台'!B5<>"",'控制台'!B4='刷新信息'!B6,'控制台'!B5='刷新信息'!B8),COUNTIF('月度趋势'!A5:A1000,A27)>0),SUMIFS('月度趋势'!D5:D1000,'月度趋势'!A5:A1000,A27,'月度趋势'!E5:E1000,"净利润"),"")

Sheet 预算输入
A1: 预算输入
A2: 每行对应公司、月份、利润项目编码；同一组合可分笔录入，按合计比较。
A4: 公司编号 | B4: 月份 | C4: 利润项目编码 | D4: 项目名称 | E4: 预算金额 | F4: 说明

Sheet 预算对比
A1: 预算对比
A2: 实际－预算；费用正差额表示超支。未录入预算时差额留空。
A4: 项目编码 | B4: 利润项目 | C4: 实际金额 | D4: 预算金额 | E4: 差额 | F4: 差异率
A5: =IF('利润表'!A5="","",'利润表'!A5) | B5: =IF('利润表'!B5="","",'利润表'!B5) | C5: =IF(AND(AND('控制台'!B4<>"",'控制台'!B5<>"",'控制台'!B4='刷新信息'!B6,'控制台'!B5='刷新信息'!B8),ISNUMBER('利润表'!C5)),'利润表'!C5,"") | D5: =IF(AND(AND('控制台'!B4<>"",'控制台'!B5<>"",'控制台'!B4='刷新信息'!B6,'控制台'!B5='刷新信息'!B8),COUNTIFS('预算输入'!A5:A204,'控制台'!B4,'预算输入'!B5:B204,'控制台'!B5,'预算输入'!C5:C204,A5)>0),SUMIFS('预算输入'!E5:E204,'预算输入'!A5:A204,'控制台'!B4,'预算输入'!B5:B204,'控制台'!B5,'预算输入'!C5:C204,A5),"") | E5: =IF(OR(D5="",C5=""),"",C5-D5) | F5: =IF(OR(D5="",D5=0),"",E5/ABS(D5))
A6: =IF('利润表'!A6="","",'利润表'!A6) | B6: =IF('利润表'!B6="","",'利润表'!B6) | C6: =IF(AND(AND('控制台'!B4<>"",'控制台'!B5<>"",'控制台'!B4='刷新信息'!B6,'控制台'!B5='刷新信息'!B8),ISNUMBER('利润表'!C6)),'利润表'!C6,"") | D6: =IF(AND(AND('控制台'!B4<>"",'控制台'!B5<>"",'控制台'!B4='刷新信息'!B6,'控制台'!B5='刷新信息'!B8),COUNTIFS('预算输入'!A5:A204,'控制台'!B4,'预算输入'!B5:B204,'控制台'!B5,'预算输入'!C5:C204,A6)>0),SUMIFS('预算输入'!E5:E204,'预算输入'!A5:A204,'控制台'!B4,'预算输入'!B5:B204,'控制台'!B5,'预算输入'!C5:C204,A6),"") | E6: =IF(OR(D6="",C6=""),"",C6-D6) | F6: =IF(OR(D6="",D6=0),"",E6/ABS(D6))
A7: =IF('利润表'!A7="","",'利润表'!A7) | B7: =IF('利润表'!B7="","",'利润表'!B7) | C7: =IF(AND(AND('控制台'!B4<>"",'控制台'!B5<>"",'控制台'!B4='刷新信息'!B6,'控制台'!B5='刷新信息'!B8),ISNUMBER('利润表'!C7)),'利润表'!C7,"") | D7: =IF(AND(AND('控制台'!B4<>"",'控制台'!B5<>"",'控制台'!B4='刷新信息'!B6,'控制台'!B5='刷新信息'!B8),COUNTIFS('预算输入'!A5:A204,'控制台'!B4,'预算输入'!B5:B204,'控制台'!B5,'预算输入'!C5:C204,A7)>0),SUMIFS('预算输入'!E5:E204,'预算输入'!A5:A204,'控制台'!B4,'预算输入'!B5:B204,'控制台'!B5,'预算输入'!C5:C204,A7),"") | E7: =IF(OR(D7="",C7=""),"",C7-D7) | F7: =IF(OR(D7="",D7=0),"",E7/ABS(D7))
A8: =IF('利润表'!A8="","",'利润表'!A8) | B8: =IF('利润表'!B8="","",'利润表'!B8) | C8: =IF(AND(AND('控制台'!B4<>"",'控制台'!B5<>"",'控制台'!B4='刷新信息'!B6,'控制台'!B5='刷新信息'!B8),ISNUMBER('利润表'!C8)),'利润表'!C8,"") | D8: =IF(AND(AND('控制台'!B4<>"",'控制台'!B5<>"",'控制台'!B4='刷新信息'!B6,'控制台'!B5='刷新信息'!B8),COUNTIFS('预算输入'!A5:A204,'控制台'!B4,'预算输入'!B5:B204,'控制台'!B5,'预算输入'!C5:C204,A8)>0),SUMIFS('预算输入'!E5:E204,'预算输入'!A5:A204,'控制台'!B4,'预算输入'!B5:B204,'控制台'!B5,'预算输入'!C5:C204,A8),"") | E8: =IF(OR(D8="",C8=""),"",C8-D8) | F8: =IF(OR(D8="",D8=0),"",E8/ABS(D8))
A9: =IF('利润表'!A9="","",'利润表'!A9) | B9: =IF('利润表'!B9="","",'利润表'!B9) | C9: =IF(AND(AND('控制台'!B4<>"",'控制台'!B5<>"",'控制台'!B4='刷新信息'!B6,'控制台'!B5='刷新信息'!B8),ISNUMBER('利润表'!C9)),'利润表'!C9,"") | D9: =IF(AND(AND('控制台'!B4<>"",'控制台'!B5<>"",'控制台'!B4='刷新信息'!B6,'控制台'!B5='刷新信息'!B8),COUNTIFS('预算输入'!A5:A204,'控制台'!B4,'预算输入'!B5:B204,'控制台'!B5,'预算输入'!C5:C204,A9)>0),SUMIFS('预算输入'!E5:E204,'预算输入'!A5:A204,'控制台'!B4,'预算输入'!B5:B204,'控制台'!B5,'预算输入'!C5:C204,A9),"") | E9: =IF(OR(D9="",C9=""),"",C9-D9) | F9: =IF(OR(D9="",D9=0),"",E9/ABS(D9))
A10: =IF('利润表'!A10="","",'利润表'!A10) | B10: =IF('利润表'!B10="","",'利润表'!B10) | C10: =IF(AND(AND('控制台'!B4<>"",'控制台'!B5<>"",'控制台'!B4='刷新信息'!B6,'控制台'!B5='刷新信息'!B8),ISNUMBER('利润表'!C10)),'利润表'!C10,"") | D10: =IF(AND(AND('控制台'!B4<>"",'控制台'!B5<>"",'控制台'!B4='刷新信息'!B6,'控制台'!B5='刷新信息'!B8),COUNTIFS('预算输入'!A5:A204,'控制台'!B4,'预算输入'!B5:B204,'控制台'!B5,'预算输入'!C5:C204,A10)>0),SUMIFS('预算输入'!E5:E204,'预算输入'!A5:A204,'控制台'!B4,'预算输入'!B5:B204,'控制台'!B5,'预算输入'!C5:C204,A10),"") | E10: =IF(OR(D10="",C10=""),"",C10-D10) | F10: =IF(OR(D10="",D10=0),"",E10/ABS(D10))
A11: =IF('利润表'!A11="","",'利润表'!A11) | B11: =IF('利润表'!B11="","",'利润表'!B11) | C11: =IF(AND(AND('控制台'!B4<>"",'控制台'!B5<>"",'控制台'!B4='刷新信息'!B6,'控制台'!B5='刷新信息'!B8),ISNUMBER('利润表'!C11)),'利润表'!C11,"") | D11: =IF(AND(AND('控制台'!B4<>"",'控制台'!B5<>"",'控制台'!B4='刷新信息'!B6,'控制台'!B5='刷新信息'!B8),COUNTIFS('预算输入'!A5:A204,'控制台'!B4,'预算输入'!B5:B204,'控制台'!B5,'预算输入'!C5:C204,A11)>0),SUMIFS('预算输入'!E5:E204,'预算输入'!A5:A204,'控制台'!B4,'预算输入'!B5:B204,'控制台'!B5,'预算输入'!C5:C204,A11),"") | E11: =IF(OR(D11="",C11=""),"",C11-D11) | F11: =IF(OR(D11="",D11=0),"",E11/ABS(D11))
A12: =IF('利润表'!A12="","",'利润表'!A12) | B12: =IF('利润表'!B12="","",'利润表'!B12) | C12: =IF(AND(AND('控制台'!B4<>"",'控制台'!B5<>"",'控制台'!B4='刷新信息'!B6,'控制台'!B5='刷新信息'!B8),ISNUMBER('利润表'!C12)),'利润表'!C12,"") | D12: =IF(AND(AND('控制台'!B4<>"",'控制台'!B5<>"",'控制台'!B4='刷新信息'!B6,'控制台'!B5='刷新信息'!B8),COUNTIFS('预算输入'!A5:A204,'控制台'!B4,'预算输入'!B5:B204,'控制台'!B5,'预算输入'!C5:C204,A12)>0),SUMIFS('预算输入'!E5:E204,'预算输入'!A5:A204,'控制台'!B4,'预算输入'!B5:B204,'控制台'!B5,'预算输入'!C5:C204,A12),"") | E12: =IF(OR(D12="",C12=""),"",C12-D12) | F12: =IF(OR(D12="",D12=0),"",E12/ABS(D12))
A13: =IF('利润表'!A13="","",'利润表'!A13) | B13: =IF('利润表'!B13="","",'利润表'!B13) | C13: =IF(AND(AND('控制台'!B4<>"",'控制台'!B5<>"",'控制台'!B4='刷新信息'!B6,'控制台'!B5='刷新信息'!B8),ISNUMBER('利润表'!C13)),'利润表'!C13,"") | D13: =IF(AND(AND('控制台'!B4<>"",'控制台'!B5<>"",'控制台'!B4='刷新信息'!B6,'控制台'!B5='刷新信息'!B8),COUNTIFS('预算输入'!A5:A204,'控制台'!B4,'预算输入'!B5:B204,'控制台'!B5,'预算输入'!C5:C204,A13)>0),SUMIFS('预算输入'!E5:E204,'预算输入'!A5:A204,'控制台'!B4,'预算输入'!B5:B204,'控制台'!B5,'预算输入'!C5:C204,A13),"") | E13: =IF(OR(D13="",C13=""),"",C13-D13) | F13: =IF(OR(D13="",D13=0),"",E13/ABS(D13))
A14: =IF('利润表'!A14="","",'利润表'!A14) | B14: =IF('利润表'!B14="","",'利润表'!B14) | C14: =IF(AND(AND('控制台'!B4<>"",'控制台'!B5<>"",'控制台'!B4='刷新信息'!B6,'控制台'!B5='刷新信息'!B8),ISNUMBER('利润表'!C14)),'利润表'!C14,"") | D14: =IF(AND(AND('控制台'!B4<>"",'控制台'!B5<>"",'控制台'!B4='刷新信息'!B6,'控制台'!B5='刷新信息'!B8),COUNTIFS('预算输入'!A5:A204,'控制台'!B4,'预算输入'!B5:B204,'控制台'!B5,'预算输入'!C5:C204,A14)>0),SUMIFS('预算输入'!E5:E204,'预算输入'!A5:A204,'控制台'!B4,'预算输入'!B5:B204,'控制台'!B5,'预算输入'!C5:C204,A14),"") | E14: =IF(OR(D14="",C14=""),"",C14-D14) | F14: =IF(OR(D14="",D14=0),"",E14/ABS(D14))
A15: =IF('利润表'!A15="","",'利润表'!A15) | B15: =IF('利润表'!B15="","",'利润表'!B15) | C15: =IF(AND(AND('控制台'!B4<>"",'控制台'!B5<>"",'控制台'!B4='刷新信息'!B6,'控制台'!B5='刷新信息'!B8),ISNUMBER('利润表'!C15)),'利润表'!C15,"") | D15: =IF(AND(AND('控制台'!B4<>"",'控制台'!B5<>"",'控制台'!B4='刷新信息'!B6,'控制台'!B5='刷新信息'!B8),COUNTIFS('预算输入'!A5:A204,'控制台'!B4,'预算输入'!B5:B204,'控制台'!B5,'预算输入'!C5:C204,A15)>0),SUMIFS('预算输入'!E5:E204,'预算输入'!A5:A204,'控制台'!B4,'预算输入'!B5:B204,'控制台'!B5,'预算输入'!C5:C204,A15),"") | E15: =IF(OR(D15="",C15=""),"",C15-D15) | F15: =IF(OR(D15="",D15=0),"",E15/ABS(D15))
A16: =IF('利润表'!A16="","",'利润表'!A16) | B16: =IF('利润表'!B16="","",'利润表'!B16) | C16: =IF(AND(AND('控制台'!B4<>"",'控制台'!B5<>"",'控制台'!B4='刷新信息'!B6,'控制台'!B5='刷新信息'!B8),ISNUMBER('利润表'!C16)),'利润表'!C16,"") | D16: =IF(AND(AND('控制台'!B4<>"",'控制台'!B5<>"",'控制台'!B4='刷新信息'!B6,'控制台'!B5='刷新信息'!B8),COUNTIFS('预算输入'!A5:A204,'控制台'!B4,'预算输入'!B5:B204,'控制台'!B5,'预算输入'!C5:C204,A16)>0),SUMIFS('预算输入'!E5:E204,'预算输入'!A5:A204,'控制台'!B4,'预算输入'!B5:B204,'控制台'!B5,'预算输入'!C5:C204,A16),"") | E16: =IF(OR(D16="",C16=""),"",C16-D16) | F16: =IF(OR(D16="",D16=0),"",E16/ABS(D16))
A17: =IF('利润表'!A17="","",'利润表'!A17) | B17: =IF('利润表'!B17="","",'利润表'!B17) | C17: =IF(AND(AND('控制台'!B4<>"",'控制台'!B5<>"",'控制台'!B4='刷新信息'!B6,'控制台'!B5='刷新信息'!B8),ISNUMBER('利润表'!C17)),'利润表'!C17,"") | D17: =IF(AND(AND('控制台'!B4<>"",'控制台'!B5<>"",'控制台'!B4='刷新信息'!B6,'控制台'!B5='刷新信息'!B8),COUNTIFS('预算输入'!A5:A204,'控制台'!B4,'预算输入'!B5:B204,'控制台'!B5,'预算输入'!C5:C204,A17)>0),SUMIFS('预算输入'!E5:E204,'预算输入'!A5:A204,'控制台'!B4,'预算输入'!B5:B204,'控制台'!B5,'预算输入'!C5:C204,A17),"") | E17: =IF(OR(D17="",C17=""),"",C17-D17) | F17: =IF(OR(D17="",D17=0),"",E17/ABS(D17))
A18: =IF('利润表'!A18="","",'利润表'!A18) | B18: =IF('利润表'!B18="","",'利润表'!B18) | C18: =IF(AND(AND('控制台'!B4<>"",'控制台'!B5<>"",'控制台'!B4='刷新信息'!B6,'控制台'!B5='刷新信息'!B8),ISNUMBER('利润表'!C18)),'利润表'!C18,"") | D18: =IF(AND(AND('控制台'!B4<>"",'控制台'!B5<>"",'控制台'!B4='刷新信息'!B6,'控制台'!B5='刷新信息'!B8),COUNTIFS('预算输入'!A5:A204,'控制台'!B4,'预算输入'!B5:B204,'控制台'!B5,'预算输入'!C5:C204,A18)>0),SUMIFS('预算输入'!E5:E204,'预算输入'!A5:A204,'控制台'!B4,'预算输入'!B5:B204,'控制台'!B5,'预算输入'!C5:C204,A18),"") | E18: =IF(OR(D18="",C18=""),"",C18-D18) | F18: =IF(OR(D18="",D18=0),"",E18/ABS(D18))
A19: =IF('利润表'!A19="","",'利润表'!A19) | B19: =IF('利润表'!B19="","",'利润表'!B19) | C19: =IF(AND(AND('控制台'!B4<>"",'控制台'!B5<>"",'控制台'!B4='刷新信息'!B6,'控制台'!B5='刷新信息'!B8),ISNUMBER('利润表'!C19)),'利润表'!C19,"") | D19: =IF(AND(AND('控制台'!B4<>"",'控制台'!B5<>"",'控制台'!B4='刷新信息'!B6,'控制台'!B5='刷新信息'!B8),COUNTIFS('预算输入'!A5:A204,'控制台'!B4,'预算输入'!B5:B204,'控制台'!B5,'预算输入'!C5:C204,A19)>0),SUMIFS('预算输入'!E5:E204,'预算输入'!A5:A204,'控制台'!B4,'预算输入'!B5:B204,'控制台'!B5,'预算输入'!C5:C204,A19),"") | E19: =IF(OR(D19="",C19=""),"",C19-D19) | F19: =IF(OR(D19="",D19=0),"",E19/ABS(D19))
A20: =IF('利润表'!A20="","",'利润表'!A20) | B20: =IF('利润表'!B20="","",'利润表'!B20) | C20: =IF(AND(AND('控制台'!B4<>"",'控制台'!B5<>"",'控制台'!B4='刷新信息'!B6,'控制台'!B5='刷新信息'!B8),ISNUMBER('利润表'!C20)),'利润表'!C20,"") | D20: =IF(AND(AND('控制台'!B4<>"",'控制台'!B5<>"",'控制台'!B4='刷新信息'!B6,'控制台'!B5='刷新信息'!B8),COUNTIFS('预算输入'!A5:A204,'控制台'!B4,'预算输入'!B5:B204,'控制台'!B5,'预算输入'!C5:C204,A20)>0),SUMIFS('预算输入'!E5:E204,'预算输入'!A5:A204,'控制台'!B4,'预算输入'!B5:B204,'控制台'!B5,'预算输入'!C5:C204,A20),"") | E20: =IF(OR(D20="",C20=""),"",C20-D20) | F20: =IF(OR(D20="",D20=0),"",E20/ABS(D20))
A21: =IF('利润表'!A21="","",'利润表'!A21) | B21: =IF('利润表'!B21="","",'利润表'!B21) | C21: =IF(AND(AND('控制台'!B4<>"",'控制台'!B5<>"",'控制台'!B4='刷新信息'!B6,'控制台'!B5='刷新信息'!B8),ISNUMBER('利润表'!C21)),'利润表'!C21,"") | D21: =IF(AND(AND('控制台'!B4<>"",'控制台'!B5<>"",'控制台'!B4='刷新信息'!B6,'控制台'!B5='刷新信息'!B8),COUNTIFS('预算输入'!A5:A204,'控制台'!B4,'预算输入'!B5:B204,'控制台'!B5,'预算输入'!C5:C204,A21)>0),SUMIFS('预算输入'!E5:E204,'预算输入'!A5:A204,'控制台'!B4,'预算输入'!B5:B204,'控制台'!B5,'预算输入'!C5:C204,A21),"") | E21: =IF(OR(D21="",C21=""),"",C21-D21) | F21: =IF(OR(D21="",D21=0),"",E21/ABS(D21))
A22: =IF('利润表'!A22="","",'利润表'!A22) | B22: =IF('利润表'!B22="","",'利润表'!B22) | C22: =IF(AND(AND('控制台'!B4<>"",'控制台'!B5<>"",'控制台'!B4='刷新信息'!B6,'控制台'!B5='刷新信息'!B8),ISNUMBER('利润表'!C22)),'利润表'!C22,"") | D22: =IF(AND(AND('控制台'!B4<>"",'控制台'!B5<>"",'控制台'!B4='刷新信息'!B6,'控制台'!B5='刷新信息'!B8),COUNTIFS('预算输入'!A5:A204,'控制台'!B4,'预算输入'!B5:B204,'控制台'!B5,'预算输入'!C5:C204,A22)>0),SUMIFS('预算输入'!E5:E204,'预算输入'!A5:A204,'控制台'!B4,'预算输入'!B5:B204,'控制台'!B5,'预算输入'!C5:C204,A22),"") | E22: =IF(OR(D22="",C22=""),"",C22-D22) | F22: =IF(OR(D22="",D22=0),"",E22/ABS(D22))
A23: =IF('利润表'!A23="","",'利润表'!A23) | B23: =IF('利润表'!B23="","",'利润表'!B23) | C23: =IF(AND(AND('控制台'!B4<>"",'控制台'!B5<>"",'控制台'!B4='刷新信息'!B6,'控制台'!B5='刷新信息'!B8),ISNUMBER('利润表'!C23)),'利润表'!C23,"") | D23: =IF(AND(AND('控制台'!B4<>"",'控制台'!B5<>"",'控制台'!B4='刷新信息'!B6,'控制台'!B5='刷新信息'!B8),COUNTIFS('预算输入'!A5:A204,'控制台'!B4,'预算输入'!B5:B204,'控制台'!B5,'预算输入'!C5:C204,A23)>0),SUMIFS('预算输入'!E5:E204,'预算输入'!A5:A204,'控制台'!B4,'预算输入'!B5:B204,'控制台'!B5,'预算输入'!C5:C204,A23),"") | E23: =IF(OR(D23="",C23=""),"",C23-D23) | F23: =IF(OR(D23="",D23=0),"",E23/ABS(D23))
A24: =IF('利润表'!A24="","",'利润表'!A24) | B24: =IF('利润表'!B24="","",'利润表'!B24) | C24: =IF(AND(AND('控制台'!B4<>"",'控制台'!B5<>"",'控制台'!B4='刷新信息'!B6,'控制台'!B5='刷新信息'!B8),ISNUMBER('利润表'!C24)),'利润表'!C24,"") | D24: =IF(AND(AND('控制台'!B4<>"",'控制台'!B5<>"",'控制台'!B4='刷新信息'!B6,'控制台'!B5='刷新信息'!B8),COUNTIFS('预算输入'!A5:A204,'控制台'!B4,'预算输入'!B5:B204,'控制台'!B5,'预算输入'!C5:C204,A24)>0),SUMIFS('预算输入'!E5:E204,'预算输入'!A5:A204,'控制台'!B4,'预算输入'!B5:B204,'控制台'!B5,'预算输入'!C5:C204,A24),"") | E24: =IF(OR(D24="",C24=""),"",C24-D24) | F24: =IF(OR(D24="",D24=0),"",E24/ABS(D24))
A25: =IF('利润表'!A25="","",'利润表'!A25) | B25: =IF('利润表'!B25="","",'利润表'!B25) | C25: =IF(AND(AND('控制台'!B4<>"",'控制台'!B5<>"",'控制台'!B4='刷新信息'!B6,'控制台'!B5='刷新信息'!B8),ISNUMBER('利润表'!C25)),'利润表'!C25,"") | D25: =IF(AND(AND('控制台'!B4<>"",'控制台'!B5<>"",'控制台'!B4='刷新信息'!B6,'控制台'!B5='刷新信息'!B8),COUNTIFS('预算输入'!A5:A204,'控制台'!B4,'预算输入'!B5:B204,'控制台'!B5,'预算输入'!C5:C204,A25)>0),SUMIFS('预算输入'!E5:E204,'预算输入'!A5:A204,'控制台'!B4,'预算输入'!B5:B204,'控制台'!B5,'预算输入'!C5:C204,A25),"") | E25: =IF(OR(D25="",C25=""),"",C25-D25) | F25: =IF(OR(D25="",D25=0),"",E25/ABS(D25))
A26: =IF('利润表'!A26="","",'利润表'!A26) | B26: =IF('利润表'!B26="","",'利润表'!B26) | C26: =IF(AND(AND('控制台'!B4<>"",'控制台'!B5<>"",'控制台'!B4='刷新信息'!B6,'控制台'!B5='刷新信息'!B8),ISNUMBER('利润表'!C26)),'利润表'!C26,"") | D26: =IF(AND(AND('控制台'!B4<>"",'控制台'!B5<>"",'控制台'!B4='刷新信息'!B6,'控制台'!B5='刷新信息'!B8),COUNTIFS('预算输入'!A5:A204,'控制台'!B4,'预算输入'!B5:B204,'控制台'!B5,'预算输入'!C5:C204,A26)>0),SUMIFS('预算输入'!E5:E204,'预算输入'!A5:A204,'控制台'!B4,'预算输入'!B5:B204,'控制台'!B5,'预算输入'!C5:C204,A26),"") | E26: =IF(OR(D26="",C26=""),"",C26-D26) | F26: =IF(OR(D26="",D26=0),"",E26/ABS(D26))
A27: =IF('利润表'!A27="","",'利润表'!A27) | B27: =IF('利润表'!B27="","",'利润表'!B27) | C27: =IF(AND(AND('控制台'!B4<>"",'控制台'!B5<>"",'控制台'!B4='刷新信息'!B6,'控制台'!B5='刷新信息'!B8),ISNUMBER('利润表'!C27)),'利润表'!C27,"") | D27: =IF(AND(AND('控制台'!B4<>"",'控制台'!B5<>"",'控制台'!B4='刷新信息'!B6,'控制台'!B5='刷新信息'!B8),COUNTIFS('预算输入'!A5:A204,'控制台'!B4,'预算输入'!B5:B204,'控制台'!B5,'预算输入'!C5:C204,A27)>0),SUMIFS('预算输入'!E5:E204,'预算输入'!A5:A204,'控制台'!B4,'预算输入'!B5:B204,'控制台'!B5,'预算输入'!C5:C204,A27),"") | E27: =IF(OR(D27="",C27=""),"",C27-D27) | F27: =IF(OR(D27="",D27=0),"",E27/ABS(D27))
A28: =IF('利润表'!A28="","",'利润表'!A28) | B28: =IF('利润表'!B28="","",'利润表'!B28) | C28: =IF(AND(AND('控制台'!B4<>"",'控制台'!B5<>"",'控制台'!B4='刷新信息'!B6,'控制台'!B5='刷新信息'!B8),ISNUMBER('利润表'!C28)),'利润表'!C28,"") | D28: =IF(AND(AND('控制台'!B4<>"",'控制台'!B5<>"",'控制台'!B4='刷新信息'!B6,'控制台'!B5='刷新信息'!B8),COUNTIFS('预算输入'!A5:A204,'控制台'!B4,'预算输入'!B5:B204,'控制台'!B5,'预算输入'!C5:C204,A28)>0),SUMIFS('预算输入'!E5:E204,'预算输入'!A5:A204,'控制台'!B4,'预算输入'!B5:B204,'控制台'!B5,'预算输入'!C5:C204,A28),"") | E28: =IF(OR(D28="",C28=""),"",C28-D28) | F28: =IF(OR(D28="",D28=0),"",E28/ABS(D28))
A29: =IF('利润表'!A29="","",'利润表'!A29) | B29: =IF('利润表'!B29="","",'利润表'!B29) | C29: =IF(AND(AND('控制台'!B4<>"",'控制台'!B5<>"",'控制台'!B4='刷新信息'!B6,'控制台'!B5='刷新信息'!B8),ISNUMBER('利润表'!C29)),'利润表'!C29,"") | D29: =IF(AND(AND('控制台'!B4<>"",'控制台'!B5<>"",'控制台'!B4='刷新信息'!B6,'控制台'!B5='刷新信息'!B8),COUNTIFS('预算输入'!A5:A204,'控制台'!B4,'预算输入'!B5:B204,'控制台'!B5,'预算输入'!C5:C204,A29)>0),SUMIFS('预算输入'!E5:E204,'预算输入'!A5:A204,'控制台'!B4,'预算输入'!B5:B204,'控制台'!B5,'预算输入'!C5:C204,A29),"") | E29: =IF(OR(D29="",C29=""),"",C29-D29) | F29: =IF(OR(D29="",D29=0),"",E29/ABS(D29))
A30: =IF('利润表'!A30="","",'利润表'!A30) | B30: =IF('利润表'!B30="","",'利润表'!B30) | C30: =IF(AND(AND('控制台'!B4<>"",'控制台'!B5<>"",'控制台'!B4='刷新信息'!B6,'控制台'!B5='刷新信息'!B8),ISNUMBER('利润表'!C30)),'利润表'!C30,"") | D30: =IF(AND(AND('控制台'!B4<>"",'控制台'!B5<>"",'控制台'!B4='刷新信息'!B6,'控制台'!B5='刷新信息'!B8),COUNTIFS('预算输入'!A5:A204,'控制台'!B4,'预算输入'!B5:B204,'控制台'!B5,'预算输入'!C5:C204,A30)>0),SUMIFS('预算输入'!E5:E204,'预算输入'!A5:A204,'控制台'!B4,'预算输入'!B5:B204,'控制台'!B5,'预算输入'!C5:C204,A30),"") | E30: =IF(OR(D30="",C30=""),"",C30-D30) | F30: =IF(OR(D30="",D30=0),"",E30/ABS(D30))
A31: =IF('利润表'!A31="","",'利润表'!A31) | B31: =IF('利润表'!B31="","",'利润表'!B31) | C31: =IF(AND(AND('控制台'!B4<>"",'控制台'!B5<>"",'控制台'!B4='刷新信息'!B6,'控制台'!B5='刷新信息'!B8),ISNUMBER('利润表'!C31)),'利润表'!C31,"") | D31: =IF(AND(AND('控制台'!B4<>"",'控制台'!B5<>"",'控制台'!B4='刷新信息'!B6,'控制台'!B5='刷新信息'!B8),COUNTIFS('预算输入'!A5:A204,'控制台'!B4,'预算输入'!B5:B204,'控制台'!B5,'预算输入'!C5:C204,A31)>0),SUMIFS('预算输入'!E5:E204,'预算输入'!A5:A204,'控制台'!B4,'预算输入'!B5:B204,'控制台'!B5,'预算输入'!C5:C204,A31),"") | E31: =IF(OR(D31="",C31=""),"",C31-D31) | F31: =IF(OR(D31="",D31=0),"",E31/ABS(D31))
A32: =IF('利润表'!A32="","",'利润表'!A32) | B32: =IF('利润表'!B32="","",'利润表'!B32) | C32: =IF(AND(AND('控制台'!B4<>"",'控制台'!B5<>"",'控制台'!B4='刷新信息'!B6,'控制台'!B5='刷新信息'!B8),ISNUMBER('利润表'!C32)),'利润表'!C32,"") | D32: =IF(AND(AND('控制台'!B4<>"",'控制台'!B5<>"",'控制台'!B4='刷新信息'!B6,'控制台'!B5='刷新信息'!B8),COUNTIFS('预算输入'!A5:A204,'控制台'!B4,'预算输入'!B5:B204,'控制台'!B5,'预算输入'!C5:C204,A32)>0),SUMIFS('预算输入'!E5:E204,'预算输入'!A5:A204,'控制台'!B4,'预算输入'!B5:B204,'控制台'!B5,'预算输入'!C5:C204,A32),"") | E32: =IF(OR(D32="",C32=""),"",C32-D32) | F32: =IF(OR(D32="",D32=0),"",E32/ABS(D32))
A33: =IF('利润表'!A33="","",'利润表'!A33) | B33: =IF('利润表'!B33="","",'利润表'!B33) | C33: =IF(AND(AND('控制台'!B4<>"",'控制台'!B5<>"",'控制台'!B4='刷新信息'!B6,'控制台'!B5='刷新信息'!B8),ISNUMBER('利润表'!C33)),'利润表'!C33,"") | D33: =IF(AND(AND('控制台'!B4<>"",'控制台'!B5<>"",'控制台'!B4='刷新信息'!B6,'控制台'!B5='刷新信息'!B8),COUNTIFS('预算输入'!A5:A204,'控制台'!B4,'预算输入'!B5:B204,'控制台'!B5,'预算输入'!C5:C204,A33)>0),SUMIFS('预算输入'!E5:E204,'预算输入'!A5:A204,'控制台'!B4,'预算输入'!B5:B204,'控制台'!B5,'预算输入'!C5:C204,A33),"") | E33: =IF(OR(D33="",C33=""),"",C33-D33) | F33: =IF(OR(D33="",D33=0),"",E33/ABS(D33))
A34: =IF('利润表'!A34="","",'利润表'!A34) | B34: =IF('利润表'!B34="","",'利润表'!B34) | C34: =IF(AND(AND('控制台'!B4<>"",'控制台'!B5<>"",'控制台'!B4='刷新信息'!B6,'控制台'!B5='刷新信息'!B8),ISNUMBER('利润表'!C34)),'利润表'!C34,"") | D34: =IF(AND(AND('控制台'!B4<>"",'控制台'!B5<>"",'控制台'!B4='刷新信息'!B6,'控制台'!B5='刷新信息'!B8),COUNTIFS('预算输入'!A5:A204,'控制台'!B4,'预算输入'!B5:B204,'控制台'!B5,'预算输入'!C5:C204,A34)>0),SUMIFS('预算输入'!E5:E204,'预算输入'!A5:A204,'控制台'!B4,'预算输入'!B5:B204,'控制台'!B5,'预算输入'!C5:C204,A34),"") | E34: =IF(OR(D34="",C34=""),"",C34-D34) | F34: =IF(OR(D34="",D34=0),"",E34/ABS(D34))
A35: =IF('利润表'!A35="","",'利润表'!A35) | B35: =IF('利润表'!B35="","",'利润表'!B35) | C35: =IF(AND(AND('控制台'!B4<>"",'控制台'!B5<>"",'控制台'!B4='刷新信息'!B6,'控制台'!B5='刷新信息'!B8),ISNUMBER('利润表'!C35)),'利润表'!C35,"") | D35: =IF(AND(AND('控制台'!B4<>"",'控制台'!B5<>"",'控制台'!B4='刷新信息'!B6,'控制台'!B5='刷新信息'!B8),COUNTIFS('预算输入'!A5:A204,'控制台'!B4,'预算输入'!B5:B204,'控制台'!B5,'预算输入'!C5:C204,A35)>0),SUMIFS('预算输入'!E5:E204,'预算输入'!A5:A204,'控制台'!B4,'预算输入'!B5:B204,'控制台'!B5,'预算输入'!C5:C204,A35),"") | E35: =IF(OR(D35="",C35=""),"",C35-D35) | F35: =IF(OR(D35="",D35=0),"",E35/ABS(D35))
A36: =IF('利润表'!A36="","",'利润表'!A36) | B36: =IF('利润表'!B36="","",'利润表'!B36) | C36: =IF(AND(AND('控制台'!B4<>"",'控制台'!B5<>"",'控制台'!B4='刷新信息'!B6,'控制台'!B5='刷新信息'!B8),ISNUMBER('利润表'!C36)),'利润表'!C36,"") | D36: =IF(AND(AND('控制台'!B4<>"",'控制台'!B5<>"",'控制台'!B4='刷新信息'!B6,'控制台'!B5='刷新信息'!B8),COUNTIFS('预算输入'!A5:A204,'控制台'!B4,'预算输入'!B5:B204,'控制台'!B5,'预算输入'!C5:C204,A36)>0),SUMIFS('预算输入'!E5:E204,'预算输入'!A5:A204,'控制台'!B4,'预算输入'!B5:B204,'控制台'!B5,'预算输入'!C5:C204,A36),"") | E36: =IF(OR(D36="",C36=""),"",C36-D36) | F36: =IF(OR(D36="",D36=0),"",E36/ABS(D36))

Sheet 账龄输入
A1: 未核销单据输入
A2: 金额为截至所选月末仍未核销的人民币余额；不是发票原始总额。项目ID从往来余额复制。
A4: 公司编号 | B4: 月份 | C4: 应收/应付 | D4: 核算项目ID组合 | E4: 单据编号 | F4: 发生日期 | G4: 到期日期 | H4: 未核销金额 | I4: 账龄天数 | J4: 逾期天数 | K4: 核验
I5: =IF(OR(A5<> '控制台'!B4,B5<> '控制台'!B5,F5=""),"",DATE(VALUE(LEFT('控制台'!B5,4)),VALUE(RIGHT('控制台'!B5,2))+1,1)-1-F5) | J5: =IF(OR(A5<> '控制台'!B4,B5<> '控制台'!B5,G5=""),"",MAX(0,DATE(VALUE(LEFT('控制台'!B5,4)),VALUE(RIGHT('控制台'!B5,2))+1,1)-1-G5)) | K5: =IF(A5="","",IF(AND(AND('控制台'!B4<>"",'控制台'!B5<>"",'控制台'!B4='刷新信息'!B6,'控制台'!B5='刷新信息'!B8),A5='控制台'!B4,B5='控制台'!B5,OR(C5="应收",C5="应付"),COUNTIFS('往来余额'!A5:A6000,C5,'往来余额'!B5:B6000,D5)=1,E5<>"",COUNTIFS(A$5:A$504,A5,B$5:B$504,B5,C$5:C$504,C5,D$5:D$504,D5,E$5:E$504,E5)=1,ISNUMBER(F5),I5>=0,ISNUMBER(H5),H5>=0),"纳入","待核实"))
I6: =IF(OR(A6<> '控制台'!B4,B6<> '控制台'!B5,F6=""),"",DATE(VALUE(LEFT('控制台'!B5,4)),VALUE(RIGHT('控制台'!B5,2))+1,1)-1-F6) | J6: =IF(OR(A6<> '控制台'!B4,B6<> '控制台'!B5,G6=""),"",MAX(0,DATE(VALUE(LEFT('控制台'!B5,4)),VALUE(RIGHT('控制台'!B5,2))+1,1)-1-G6)) | K6: =IF(A6="","",IF(AND(AND('控制台'!B4<>"",'控制台'!B5<>"",'控制台'!B4='刷新信息'!B6,'控制台'!B5='刷新信息'!B8),A6='控制台'!B4,B6='控制台'!B5,OR(C6="应收",C6="应付"),COUNTIFS('往来余额'!A5:A6000,C6,'往来余额'!B5:B6000,D6)=1,E6<>"",COUNTIFS(A$5:A$504,A6,B$5:B$504,B6,C$5:C$504,C6,D$5:D$504,D6,E$5:E$504,E6)=1,ISNUMBER(F6),I6>=0,ISNUMBER(H6),H6>=0),"纳入","待核实"))
I7: =IF(OR(A7<> '控制台'!B4,B7<> '控制台'!B5,F7=""),"",DATE(VALUE(LEFT('控制台'!B5,4)),VALUE(RIGHT('控制台'!B5,2))+1,1)-1-F7) | J7: =IF(OR(A7<> '控制台'!B4,B7<> '控制台'!B5,G7=""),"",MAX(0,DATE(VALUE(LEFT('控制台'!B5,4)),VALUE(RIGHT('控制台'!B5,2))+1,1)-1-G7)) | K7: =IF(A7="","",IF(AND(AND('控制台'!B4<>"",'控制台'!B5<>"",'控制台'!B4='刷新信息'!B6,'控制台'!B5='刷新信息'!B8),A7='控制台'!B4,B7='控制台'!B5,OR(C7="应收",C7="应付"),COUNTIFS('往来余额'!A5:A6000,C7,'往来余额'!B5:B6000,D7)=1,E7<>"",COUNTIFS(A$5:A$504,A7,B$5:B$504,B7,C$5:C$504,C7,D$5:D$504,D7,E$5:E$504,E7)=1,ISNUMBER(F7),I7>=0,ISNUMBER(H7),H7>=0),"纳入","待核实"))
I8: =IF(OR(A8<> '控制台'!B4,B8<> '控制台'!B5,F8=""),"",DATE(VALUE(LEFT('控制台'!B5,4)),VALUE(RIGHT('控制台'!B5,2))+1,1)-1-F8) | J8: =IF(OR(A8<> '控制台'!B4,B8<> '控制台'!B5,G8=""),"",MAX(0,DATE(VALUE(LEFT('控制台'!B5,4)),VALUE(RIGHT('控制台'!B5,2))+1,1)-1-G8)) | K8: =IF(A8="","",IF(AND(AND('控制台'!B4<>"",'控制台'!B5<>"",'控制台'!B4='刷新信息'!B6,'控制台'!B5='刷新信息'!B8),A8='控制台'!B4,B8='控制台'!B5,OR(C8="应收",C8="应付"),COUNTIFS('往来余额'!A5:A6000,C8,'往来余额'!B5:B6000,D8)=1,E8<>"",COUNTIFS(A$5:A$504,A8,B$5:B$504,B8,C$5:C$504,C8,D$5:D$504,D8,E$5:E$504,E8)=1,ISNUMBER(F8),I8>=0,ISNUMBER(H8),H8>=0),"纳入","待核实"))
I9: =IF(OR(A9<> '控制台'!B4,B9<> '控制台'!B5,F9=""),"",DATE(VALUE(LEFT('控制台'!B5,4)),VALUE(RIGHT('控制台'!B5,2))+1,1)-1-F9) | J9: =IF(OR(A9<> '控制台'!B4,B9<> '控制台'!B5,G9=""),"",MAX(0,DATE(VALUE(LEFT('控制台'!B5,4)),VALUE(RIGHT('控制台'!B5,2))+1,1)-1-G9)) | K9: =IF(A9="","",IF(AND(AND('控制台'!B4<>"",'控制台'!B5<>"",'控制台'!B4='刷新信息'!B6,'控制台'!B5='刷新信息'!B8),A9='控制台'!B4,B9='控制台'!B5,OR(C9="应收",C9="应付"),COUNTIFS('往来余额'!A5:A6000,C9,'往来余额'!B5:B6000,D9)=1,E9<>"",COUNTIFS(A$5:A$504,A9,B$5:B$504,B9,C$5:C$504,C9,D$5:D$504,D9,E$5:E$504,E9)=1,ISNUMBER(F9),I9>=0,ISNUMBER(H9),H9>=0),"纳入","待核实"))
I10: =IF(OR(A10<> '控制台'!B4,B10<> '控制台'!B5,F10=""),"",DATE(VALUE(LEFT('控制台'!B5,4)),VALUE(RIGHT('控制台'!B5,2))+1,1)-1-F10) | J10: =IF(OR(A10<> '控制台'!B4,B10<> '控制台'!B5,G10=""),"",MAX(0,DATE(VALUE(LEFT('控制台'!B5,4)),VALUE(RIGHT('控制台'!B5,2))+1,1)-1-G10)) | K10: =IF(A10="","",IF(AND(AND('控制台'!B4<>"",'控制台'!B5<>"",'控制台'!B4='刷新信息'!B6,'控制台'!B5='刷新信息'!B8),A10='控制台'!B4,B10='控制台'!B5,OR(C10="应收",C10="应付"),COUNTIFS('往来余额'!A5:A6000,C10,'往来余额'!B5:B6000,D10)=1,E10<>"",COUNTIFS(A$5:A$504,A10,B$5:B$504,B10,C$5:C$504,C10,D$5:D$504,D10,E$5:E$504,E10)=1,ISNUMBER(F10),I10>=0,ISNUMBER(H10),H10>=0),"纳入","待核实"))
I11: =IF(OR(A11<> '控制台'!B4,B11<> '控制台'!B5,F11=""),"",DATE(VALUE(LEFT('控制台'!B5,4)),VALUE(RIGHT('控制台'!B5,2))+1,1)-1-F11) | J11: =IF(OR(A11<> '控制台'!B4,B11<> '控制台'!B5,G11=""),"",MAX(0,DATE(VALUE(LEFT('控制台'!B5,4)),VALUE(RIGHT('控制台'!B5,2))+1,1)-1-G11)) | K11: =IF(A11="","",IF(AND(AND('控制台'!B4<>"",'控制台'!B5<>"",'控制台'!B4='刷新信息'!B6,'控制台'!B5='刷新信息'!B8),A11='控制台'!B4,B11='控制台'!B5,OR(C11="应收",C11="应付"),COUNTIFS('往来余额'!A5:A6000,C11,'往来余额'!B5:B6000,D11)=1,E11<>"",COUNTIFS(A$5:A$504,A11,B$5:B$504,B11,C$5:C$504,C11,D$5:D$504,D11,E$5:E$504,E11)=1,ISNUMBER(F11),I11>=0,ISNUMBER(H11),H11>=0),"纳入","待核实"))
I12: =IF(OR(A12<> '控制台'!B4,B12<> '控制台'!B5,F12=""),"",DATE(VALUE(LEFT('控制台'!B5,4)),VALUE(RIGHT('控制台'!B5,2))+1,1)-1-F12) | J12: =IF(OR(A12<> '控制台'!B4,B12<> '控制台'!B5,G12=""),"",MAX(0,DATE(VALUE(LEFT('控制台'!B5,4)),VALUE(RIGHT('控制台'!B5,2))+1,1)-1-G12)) | K12: =IF(A12="","",IF(AND(AND('控制台'!B4<>"",'控制台'!B5<>"",'控制台'!B4='刷新信息'!B6,'控制台'!B5='刷新信息'!B8),A12='控制台'!B4,B12='控制台'!B5,OR(C12="应收",C12="应付"),COUNTIFS('往来余额'!A5:A6000,C12,'往来余额'!B5:B6000,D12)=1,E12<>"",COUNTIFS(A$5:A$504,A12,B$5:B$504,B12,C$5:C$504,C12,D$5:D$504,D12,E$5:E$504,E12)=1,ISNUMBER(F12),I12>=0,ISNUMBER(H12),H12>=0),"纳入","待核实"))
I13: =IF(OR(A13<> '控制台'!B4,B13<> '控制台'!B5,F13=""),"",DATE(VALUE(LEFT('控制台'!B5,4)),VALUE(RIGHT('控制台'!B5,2))+1,1)-1-F13) | J13: =IF(OR(A13<> '控制台'!B4,B13<> '控制台'!B5,G13=""),"",MAX(0,DATE(VALUE(LEFT('控制台'!B5,4)),VALUE(RIGHT('控制台'!B5,2))+1,1)-1-G13)) | K13: =IF(A13="","",IF(AND(AND('控制台'!B4<>"",'控制台'!B5<>"",'控制台'!B4='刷新信息'!B6,'控制台'!B5='刷新信息'!B8),A13='控制台'!B4,B13='控制台'!B5,OR(C13="应收",C13="应付"),COUNTIFS('往来余额'!A5:A6000,C13,'往来余额'!B5:B6000,D13)=1,E13<>"",COUNTIFS(A$5:A$504,A13,B$5:B$504,B13,C$5:C$504,C13,D$5:D$504,D13,E$5:E$504,E13)=1,ISNUMBER(F13),I13>=0,ISNUMBER(H13),H13>=0),"纳入","待核实"))
I14: =IF(OR(A14<> '控制台'!B4,B14<> '控制台'!B5,F14=""),"",DATE(VALUE(LEFT('控制台'!B5,4)),VALUE(RIGHT('控制台'!B5,2))+1,1)-1-F14) | J14: =IF(OR(A14<> '控制台'!B4,B14<> '控制台'!B5,G14=""),"",MAX(0,DATE(VALUE(LEFT('控制台'!B5,4)),VALUE(RIGHT('控制台'!B5,2))+1,1)-1-G14)) | K14: =IF(A14="","",IF(AND(AND('控制台'!B4<>"",'控制台'!B5<>"",'控制台'!B4='刷新信息'!B6,'控制台'!B5='刷新信息'!B8),A14='控制台'!B4,B14='控制台'!B5,OR(C14="应收",C14="应付"),COUNTIFS('往来余额'!A5:A6000,C14,'往来余额'!B5:B6000,D14)=1,E14<>"",COUNTIFS(A$5:A$504,A14,B$5:B$504,B14,C$5:C$504,C14,D$5:D$504,D14,E$5:E$504,E14)=1,ISNUMBER(F14),I14>=0,ISNUMBER(H14),H14>=0),"纳入","待核实"))
I15: =IF(OR(A15<> '控制台'!B4,B15<> '控制台'!B5,F15=""),"",DATE(VALUE(LEFT('控制台'!B5,4)),VALUE(RIGHT('控制台'!B5,2))+1,1)-1-F15) | J15: =IF(OR(A15<> '控制台'!B4,B15<> '控制台'!B5,G15=""),"",MAX(0,DATE(VALUE(LEFT('控制台'!B5,4)),VALUE(RIGHT('控制台'!B5,2))+1,1)-1-G15)) | K15: =IF(A15="","",IF(AND(AND('控制台'!B4<>"",'控制台'!B5<>"",'控制台'!B4='刷新信息'!B6,'控制台'!B5='刷新信息'!B8),A15='控制台'!B4,B15='控制台'!B5,OR(C15="应收",C15="应付"),COUNTIFS('往来余额'!A5:A6000,C15,'往来余额'!B5:B6000,D15)=1,E15<>"",COUNTIFS(A$5:A$504,A15,B$5:B$504,B15,C$5:C$504,C15,D$5:D$504,D15,E$5:E$504,E15)=1,ISNUMBER(F15),I15>=0,ISNUMBER(H15),H15>=0),"纳入","待核实"))
I16: =IF(OR(A16<> '控制台'!B4,B16<> '控制台'!B5,F16=""),"",DATE(VALUE(LEFT('控制台'!B5,4)),VALUE(RIGHT('控制台'!B5,2))+1,1)-1-F16) | J16: =IF(OR(A16<> '控制台'!B4,B16<> '控制台'!B5,G16=""),"",MAX(0,DATE(VALUE(LEFT('控制台'!B5,4)),VALUE(RIGHT('控制台'!B5,2))+1,1)-1-G16)) | K16: =IF(A16="","",IF(AND(AND('控制台'!B4<>"",'控制台'!B5<>"",'控制台'!B4='刷新信息'!B6,'控制台'!B5='刷新信息'!B8),A16='控制台'!B4,B16='控制台'!B5,OR(C16="应收",C16="应付"),COUNTIFS('往来余额'!A5:A6000,C16,'往来余额'!B5:B6000,D16)=1,E16<>"",COUNTIFS(A$5:A$504,A16,B$5:B$504,B16,C$5:C$504,C16,D$5:D$504,D16,E$5:E$504,E16)=1,ISNUMBER(F16),I16>=0,ISNUMBER(H16),H16>=0),"纳入","待核实"))
I17: =IF(OR(A17<> '控制台'!B4,B17<> '控制台'!B5,F17=""),"",DATE(VALUE(LEFT('控制台'!B5,4)),VALUE(RIGHT('控制台'!B5,2))+1,1)-1-F17) | J17: =IF(OR(A17<> '控制台'!B4,B17<> '控制台'!B5,G17=""),"",MAX(0,DATE(VALUE(LEFT('控制台'!B5,4)),VALUE(RIGHT('控制台'!B5,2))+1,1)-1-G17)) | K17: =IF(A17="","",IF(AND(AND('控制台'!B4<>"",'控制台'!B5<>"",'控制台'!B4='刷新信息'!B6,'控制台'!B5='刷新信息'!B8),A17='控制台'!B4,B17='控制台'!B5,OR(C17="应收",C17="应付"),COUNTIFS('往来余额'!A5:A6000,C17,'往来余额'!B5:B6000,D17)=1,E17<>"",COUNTIFS(A$5:A$504,A17,B$5:B$504,B17,C$5:C$504,C17,D$5:D$504,D17,E$5:E$504,E17)=1,ISNUMBER(F17),I17>=0,ISNUMBER(H17),H17>=0),"纳入","待核实"))
I18: =IF(OR(A18<> '控制台'!B4,B18<> '控制台'!B5,F18=""),"",DATE(VALUE(LEFT('控制台'!B5,4)),VALUE(RIGHT('控制台'!B5,2))+1,1)-1-F18) | J18: =IF(OR(A18<> '控制台'!B4,B18<> '控制台'!B5,G18=""),"",MAX(0,DATE(VALUE(LEFT('控制台'!B5,4)),VALUE(RIGHT('控制台'!B5,2))+1,1)-1-G18)) | K18: =IF(A18="","",IF(AND(AND('控制台'!B4<>"",'控制台'!B5<>"",'控制台'!B4='刷新信息'!B6,'控制台'!B5='刷新信息'!B8),A18='控制台'!B4,B18='控制台'!B5,OR(C18="应收",C18="应付"),COUNTIFS('往来余额'!A5:A6000,C18,'往来余额'!B5:B6000,D18)=1,E18<>"",COUNTIFS(A$5:A$504,A18,B$5:B$504,B18,C$5:C$504,C18,D$5:D$504,D18,E$5:E$504,E18)=1,ISNUMBER(F18),I18>=0,ISNUMBER(H18),H18>=0),"纳入","待核实"))
I19: =IF(OR(A19<> '控制台'!B4,B19<> '控制台'!B5,F19=""),"",DATE(VALUE(LEFT('控制台'!B5,4)),VALUE(RIGHT('控制台'!B5,2))+1,1)-1-F19) | J19: =IF(OR(A19<> '控制台'!B4,B19<> '控制台'!B5,G19=""),"",MAX(0,DATE(VALUE(LEFT('控制台'!B5,4)),VALUE(RIGHT('控制台'!B5,2))+1,1)-1-G19)) | K19: =IF(A19="","",IF(AND(AND('控制台'!B4<>"",'控制台'!B5<>"",'控制台'!B4='刷新信息'!B6,'控制台'!B5='刷新信息'!B8),A19='控制台'!B4,B19='控制台'!B5,OR(C19="应收",C19="应付"),COUNTIFS('往来余额'!A5:A6000,C19,'往来余额'!B5:B6000,D19)=1,E19<>"",COUNTIFS(A$5:A$504,A19,B$5:B$504,B19,C$5:C$504,C19,D$5:D$504,D19,E$5:E$504,E19)=1,ISNUMBER(F19),I19>=0,ISNUMBER(H19),H19>=0),"纳入","待核实"))
I20: =IF(OR(A20<> '控制台'!B4,B20<> '控制台'!B5,F20=""),"",DATE(VALUE(LEFT('控制台'!B5,4)),VALUE(RIGHT('控制台'!B5,2))+1,1)-1-F20) | J20: =IF(OR(A20<> '控制台'!B4,B20<> '控制台'!B5,G20=""),"",MAX(0,DATE(VALUE(LEFT('控制台'!B5,4)),VALUE(RIGHT('控制台'!B5,2))+1,1)-1-G20)) | K20: =IF(A20="","",IF(AND(AND('控制台'!B4<>"",'控制台'!B5<>"",'控制台'!B4='刷新信息'!B6,'控制台'!B5='刷新信息'!B8),A20='控制台'!B4,B20='控制台'!B5,OR(C20="应收",C20="应付"),COUNTIFS('往来余额'!A5:A6000,C20,'往来余额'!B5:B6000,D20)=1,E20<>"",COUNTIFS(A$5:A$504,A20,B$5:B$504,B20,C$5:C$504,C20,D$5:D$504,D20,E$5:E$504,E20)=1,ISNUMBER(F20),I20>=0,ISNUMBER(H20),H20>=0),"纳入","待核实"))
I21: =IF(OR(A21<> '控制台'!B4,B21<> '控制台'!B5,F21=""),"",DATE(VALUE(LEFT('控制台'!B5,4)),VALUE(RIGHT('控制台'!B5,2))+1,1)-1-F21) | J21: =IF(OR(A21<> '控制台'!B4,B21<> '控制台'!B5,G21=""),"",MAX(0,DATE(VALUE(LEFT('控制台'!B5,4)),VALUE(RIGHT('控制台'!B5,2))+1,1)-1-G21)) | K21: =IF(A21="","",IF(AND(AND('控制台'!B4<>"",'控制台'!B5<>"",'控制台'!B4='刷新信息'!B6,'控制台'!B5='刷新信息'!B8),A21='控制台'!B4,B21='控制台'!B5,OR(C21="应收",C21="应付"),COUNTIFS('往来余额'!A5:A6000,C21,'往来余额'!B5:B6000,D21)=1,E21<>"",COUNTIFS(A$5:A$504,A21,B$5:B$504,B21,C$5:C$504,C21,D$5:D$504,D21,E$5:E$504,E21)=1,ISNUMBER(F21),I21>=0,ISNUMBER(H21),H21>=0),"纳入","待核实"))
I22: =IF(OR(A22<> '控制台'!B4,B22<> '控制台'!B5,F22=""),"",DATE(VALUE(LEFT('控制台'!B5,4)),VALUE(RIGHT('控制台'!B5,2))+1,1)-1-F22) | J22: =IF(OR(A22<> '控制台'!B4,B22<> '控制台'!B5,G22=""),"",MAX(0,DATE(VALUE(LEFT('控制台'!B5,4)),VALUE(RIGHT('控制台'!B5,2))+1,1)-1-G22)) | K22: =IF(A22="","",IF(AND(AND('控制台'!B4<>"",'控制台'!B5<>"",'控制台'!B4='刷新信息'!B6,'控制台'!B5='刷新信息'!B8),A22='控制台'!B4,B22='控制台'!B5,OR(C22="应收",C22="应付"),COUNTIFS('往来余额'!A5:A6000,C22,'往来余额'!B5:B6000,D22)=1,E22<>"",COUNTIFS(A$5:A$504,A22,B$5:B$504,B22,C$5:C$504,C22,D$5:D$504,D22,E$5:E$504,E22)=1,ISNUMBER(F22),I22>=0,ISNUMBER(H22),H22>=0),"纳入","待核实"))
I23: =IF(OR(A23<> '控制台'!B4,B23<> '控制台'!B5,F23=""),"",DATE(VALUE(LEFT('控制台'!B5,4)),VALUE(RIGHT('控制台'!B5,2))+1,1)-1-F23) | J23: =IF(OR(A23<> '控制台'!B4,B23<> '控制台'!B5,G23=""),"",MAX(0,DATE(VALUE(LEFT('控制台'!B5,4)),VALUE(RIGHT('控制台'!B5,2))+1,1)-1-G23)) | K23: =IF(A23="","",IF(AND(AND('控制台'!B4<>"",'控制台'!B5<>"",'控制台'!B4='刷新信息'!B6,'控制台'!B5='刷新信息'!B8),A23='控制台'!B4,B23='控制台'!B5,OR(C23="应收",C23="应付"),COUNTIFS('往来余额'!A5:A6000,C23,'往来余额'!B5:B6000,D23)=1,E23<>"",COUNTIFS(A$5:A$504,A23,B$5:B$504,B23,C$5:C$504,C23,D$5:D$504,D23,E$5:E$504,E23)=1,ISNUMBER(F23),I23>=0,ISNUMBER(H23),H23>=0),"纳入","待核实"))
I24: =IF(OR(A24<> '控制台'!B4,B24<> '控制台'!B5,F24=""),"",DATE(VALUE(LEFT('控制台'!B5,4)),VALUE(RIGHT('控制台'!B5,2))+1,1)-1-F24) | J24: =IF(OR(A24<> '控制台'!B4,B24<> '控制台'!B5,G24=""),"",MAX(0,DATE(VALUE(LEFT('控制台'!B5,4)),VALUE(RIGHT('控制台'!B5,2))+1,1)-1-G24)) | K24: =IF(A24="","",IF(AND(AND('控制台'!B4<>"",'控制台'!B5<>"",'控制台'!B4='刷新信息'!B6,'控制台'!B5='刷新信息'!B8),A24='控制台'!B4,B24='控制台'!B5,OR(C24="应收",C24="应付"),COUNTIFS('往来余额'!A5:A6000,C24,'往来余额'!B5:B6000,D24)=1,E24<>"",COUNTIFS(A$5:A$504,A24,B$5:B$504,B24,C$5:C$504,C24,D$5:D$504,D24,E$5:E$504,E24)=1,ISNUMBER(F24),I24>=0,ISNUMBER(H24),H24>=0),"纳入","待核实"))
I25: =IF(OR(A25<> '控制台'!B4,B25<> '控制台'!B5,F25=""),"",DATE(VALUE(LEFT('控制台'!B5,4)),VALUE(RIGHT('控制台'!B5,2))+1,1)-1-F25) | J25: =IF(OR(A25<> '控制台'!B4,B25<> '控制台'!B5,G25=""),"",MAX(0,DATE(VALUE(LEFT('控制台'!B5,4)),VALUE(RIGHT('控制台'!B5,2))+1,1)-1-G25)) | K25: =IF(A25="","",IF(AND(AND('控制台'!B4<>"",'控制台'!B5<>"",'控制台'!B4='刷新信息'!B6,'控制台'!B5='刷新信息'!B8),A25='控制台'!B4,B25='控制台'!B5,OR(C25="应收",C25="应付"),COUNTIFS('往来余额'!A5:A6000,C25,'往来余额'!B5:B6000,D25)=1,E25<>"",COUNTIFS(A$5:A$504,A25,B$5:B$504,B25,C$5:C$504,C25,D$5:D$504,D25,E$5:E$504,E25)=1,ISNUMBER(F25),I25>=0,ISNUMBER(H25),H25>=0),"纳入","待核实"))
I26: =IF(OR(A26<> '控制台'!B4,B26<> '控制台'!B5,F26=""),"",DATE(VALUE(LEFT('控制台'!B5,4)),VALUE(RIGHT('控制台'!B5,2))+1,1)-1-F26) | J26: =IF(OR(A26<> '控制台'!B4,B26<> '控制台'!B5,G26=""),"",MAX(0,DATE(VALUE(LEFT('控制台'!B5,4)),VALUE(RIGHT('控制台'!B5,2))+1,1)-1-G26)) | K26: =IF(A26="","",IF(AND(AND('控制台'!B4<>"",'控制台'!B5<>"",'控制台'!B4='刷新信息'!B6,'控制台'!B5='刷新信息'!B8),A26='控制台'!B4,B26='控制台'!B5,OR(C26="应收",C26="应付"),COUNTIFS('往来余额'!A5:A6000,C26,'往来余额'!B5:B6000,D26)=1,E26<>"",COUNTIFS(A$5:A$504,A26,B$5:B$504,B26,C$5:C$504,C26,D$5:D$504,D26,E$5:E$504,E26)=1,ISNUMBER(F26),I26>=0,ISNUMBER(H26),H26>=0),"纳入","待核实"))
I27: =IF(OR(A27<> '控制台'!B4,B27<> '控制台'!B5,F27=""),"",DATE(VALUE(LEFT('控制台'!B5,4)),VALUE(RIGHT('控制台'!B5,2))+1,1)-1-F27) | J27: =IF(OR(A27<> '控制台'!B4,B27<> '控制台'!B5,G27=""),"",MAX(0,DATE(VALUE(LEFT('控制台'!B5,4)),VALUE(RIGHT('控制台'!B5,2))+1,1)-1-G27)) | K27: =IF(A27="","",IF(AND(AND('控制台'!B4<>"",'控制台'!B5<>"",'控制台'!B4='刷新信息'!B6,'控制台'!B5='刷新信息'!B8),A27='控制台'!B4,B27='控制台'!B5,OR(C27="应收",C27="应付"),COUNTIFS('往来余额'!A5:A6000,C27,'往来余额'!B5:B6000,D27)=1,E27<>"",COUNTIFS(A$5:A$504,A27,B$5:B$504,B27,C$5:C$504,C27,D$5:D$504,D27,E$5:E$504,E27)=1,ISNUMBER(F27),I27>=0,ISNUMBER(H27),H27>=0),"纳入","待核实"))
I28: =IF(OR(A28<> '控制台'!B4,B28<> '控制台'!B5,F28=""),"",DATE(VALUE(LEFT('控制台'!B5,4)),VALUE(RIGHT('控制台'!B5,2))+1,1)-1-F28) | J28: =IF(OR(A28<> '控制台'!B4,B28<> '控制台'!B5,G28=""),"",MAX(0,DATE(VALUE(LEFT('控制台'!B5,4)),VALUE(RIGHT('控制台'!B5,2))+1,1)-1-G28)) | K28: =IF(A28="","",IF(AND(AND('控制台'!B4<>"",'控制台'!B5<>"",'控制台'!B4='刷新信息'!B6,'控制台'!B5='刷新信息'!B8),A28='控制台'!B4,B28='控制台'!B5,OR(C28="应收",C28="应付"),COUNTIFS('往来余额'!A5:A6000,C28,'往来余额'!B5:B6000,D28)=1,E28<>"",COUNTIFS(A$5:A$504,A28,B$5:B$504,B28,C$5:C$504,C28,D$5:D$504,D28,E$5:E$504,E28)=1,ISNUMBER(F28),I28>=0,ISNUMBER(H28),H28>=0),"纳入","待核实"))
I29: =IF(OR(A29<> '控制台'!B4,B29<> '控制台'!B5,F29=""),"",DATE(VALUE(LEFT('控制台'!B5,4)),VALUE(RIGHT('控制台'!B5,2))+1,1)-1-F29) | J29: =IF(OR(A29<> '控制台'!B4,B29<> '控制台'!B5,G29=""),"",MAX(0,DATE(VALUE(LEFT('控制台'!B5,4)),VALUE(RIGHT('控制台'!B5,2))+1,1)-1-G29)) | K29: =IF(A29="","",IF(AND(AND('控制台'!B4<>"",'控制台'!B5<>"",'控制台'!B4='刷新信息'!B6,'控制台'!B5='刷新信息'!B8),A29='控制台'!B4,B29='控制台'!B5,OR(C29="应收",C29="应付"),COUNTIFS('往来余额'!A5:A6000,C29,'往来余额'!B5:B6000,D29)=1,E29<>"",COUNTIFS(A$5:A$504,A29,B$5:B$504,B29,C$5:C$504,C29,D$5:D$504,D29,E$5:E$504,E29)=1,ISNUMBER(F29),I29>=0,ISNUMBER(H29),H29>=0),"纳入","待核实"))
I30: =IF(OR(A30<> '控制台'!B4,B30<> '控制台'!B5,F30=""),"",DATE(VALUE(LEFT('控制台'!B5,4)),VALUE(RIGHT('控制台'!B5,2))+1,1)-1-F30) | J30: =IF(OR(A30<> '控制台'!B4,B30<> '控制台'!B5,G30=""),"",MAX(0,DATE(VALUE(LEFT('控制台'!B5,4)),VALUE(RIGHT('控制台'!B5,2))+1,1)-1-G30)) | K30: =IF(A30="","",IF(AND(AND('控制台'!B4<>"",'控制台'!B5<>"",'控制台'!B4='刷新信息'!B6,'控制台'!B5='刷新信息'!B8),A30='控制台'!B4,B30='控制台'!B5,OR(C30="应收",C30="应付"),COUNTIFS('往来余额'!A5:A6000,C30,'往来余额'!B5:B6000,D30)=1,E30<>"",COUNTIFS(A$5:A$504,A30,B$5:B$504,B30,C$5:C$504,C30,D$5:D$504,D30,E$5:E$504,E30)=1,ISNUMBER(F30),I30>=0,ISNUMBER(H30),H30>=0),"纳入","待核实"))
I31: =IF(OR(A31<> '控制台'!B4,B31<> '控制台'!B5,F31=""),"",DATE(VALUE(LEFT('控制台'!B5,4)),VALUE(RIGHT('控制台'!B5,2))+1,1)-1-F31) | J31: =IF(OR(A31<> '控制台'!B4,B31<> '控制台'!B5,G31=""),"",MAX(0,DATE(VALUE(LEFT('控制台'!B5,4)),VALUE(RIGHT('控制台'!B5,2))+1,1)-1-G31)) | K31: =IF(A31="","",IF(AND(AND('控制台'!B4<>"",'控制台'!B5<>"",'控制台'!B4='刷新信息'!B6,'控制台'!B5='刷新信息'!B8),A31='控制台'!B4,B31='控制台'!B5,OR(C31="应收",C31="应付"),COUNTIFS('往来余额'!A5:A6000,C31,'往来余额'!B5:B6000,D31)=1,E31<>"",COUNTIFS(A$5:A$504,A31,B$5:B$504,B31,C$5:C$504,C31,D$5:D$504,D31,E$5:E$504,E31)=1,ISNUMBER(F31),I31>=0,ISNUMBER(H31),H31>=0),"纳入","待核实"))
I32: =IF(OR(A32<> '控制台'!B4,B32<> '控制台'!B5,F32=""),"",DATE(VALUE(LEFT('控制台'!B5,4)),VALUE(RIGHT('控制台'!B5,2))+1,1)-1-F32) | J32: =IF(OR(A32<> '控制台'!B4,B32<> '控制台'!B5,G32=""),"",MAX(0,DATE(VALUE(LEFT('控制台'!B5,4)),VALUE(RIGHT('控制台'!B5,2))+1,1)-1-G32)) | K32: =IF(A32="","",IF(AND(AND('控制台'!B4<>"",'控制台'!B5<>"",'控制台'!B4='刷新信息'!B6,'控制台'!B5='刷新信息'!B8),A32='控制台'!B4,B32='控制台'!B5,OR(C32="应收",C32="应付"),COUNTIFS('往来余额'!A5:A6000,C32,'往来余额'!B5:B6000,D32)=1,E32<>"",COUNTIFS(A$5:A$504,A32,B$5:B$504,B32,C$5:C$504,C32,D$5:D$504,D32,E$5:E$504,E32)=1,ISNUMBER(F32),I32>=0,ISNUMBER(H32),H32>=0),"纳入","待核实"))
I33: =IF(OR(A33<> '控制台'!B4,B33<> '控制台'!B5,F33=""),"",DATE(VALUE(LEFT('控制台'!B5,4)),VALUE(RIGHT('控制台'!B5,2))+1,1)-1-F33) | J33: =IF(OR(A33<> '控制台'!B4,B33<> '控制台'!B5,G33=""),"",MAX(0,DATE(VALUE(LEFT('控制台'!B5,4)),VALUE(RIGHT('控制台'!B5,2))+1,1)-1-G33)) | K33: =IF(A33="","",IF(AND(AND('控制台'!B4<>"",'控制台'!B5<>"",'控制台'!B4='刷新信息'!B6,'控制台'!B5='刷新信息'!B8),A33='控制台'!B4,B33='控制台'!B5,OR(C33="应收",C33="应付"),COUNTIFS('往来余额'!A5:A6000,C33,'往来余额'!B5:B6000,D33)=1,E33<>"",COUNTIFS(A$5:A$504,A33,B$5:B$504,B33,C$5:C$504,C33,D$5:D$504,D33,E$5:E$504,E33)=1,ISNUMBER(F33),I33>=0,ISNUMBER(H33),H33>=0),"纳入","待核实"))
I34: =IF(OR(A34<> '控制台'!B4,B34<> '控制台'!B5,F34=""),"",DATE(VALUE(LEFT('控制台'!B5,4)),VALUE(RIGHT('控制台'!B5,2))+1,1)-1-F34) | J34: =IF(OR(A34<> '控制台'!B4,B34<> '控制台'!B5,G34=""),"",MAX(0,DATE(VALUE(LEFT('控制台'!B5,4)),VALUE(RIGHT('控制台'!B5,2))+1,1)-1-G34)) | K34: =IF(A34="","",IF(AND(AND('控制台'!B4<>"",'控制台'!B5<>"",'控制台'!B4='刷新信息'!B6,'控制台'!B5='刷新信息'!B8),A34='控制台'!B4,B34='控制台'!B5,OR(C34="应收",C34="应付"),COUNTIFS('往来余额'!A5:A6000,C34,'往来余额'!B5:B6000,D34)=1,E34<>"",COUNTIFS(A$5:A$504,A34,B$5:B$504,B34,C$5:C$504,C34,D$5:D$504,D34,E$5:E$504,E34)=1,ISNUMBER(F34),I34>=0,ISNUMBER(H34),H34>=0),"纳入","待核实"))
I35: =IF(OR(A35<> '控制台'!B4,B35<> '控制台'!B5,F35=""),"",DATE(VALUE(LEFT('控制台'!B5,4)),VALUE(RIGHT('控制台'!B5,2))+1,1)-1-F35) | J35: =IF(OR(A35<> '控制台'!B4,B35<> '控制台'!B5,G35=""),"",MAX(0,DATE(VALUE(LEFT('控制台'!B5,4)),VALUE(RIGHT('控制台'!B5,2))+1,1)-1-G35)) | K35: =IF(A35="","",IF(AND(AND('控制台'!B4<>"",'控制台'!B5<>"",'控制台'!B4='刷新信息'!B6,'控制台'!B5='刷新信息'!B8),A35='控制台'!B4,B35='控制台'!B5,OR(C35="应收",C35="应付"),COUNTIFS('往来余额'!A5:A6000,C35,'往来余额'!B5:B6000,D35)=1,E35<>"",COUNTIFS(A$5:A$504,A35,B$5:B$504,B35,C$5:C$504,C35,D$5:D$504,D35,E$5:E$504,E35)=1,ISNUMBER(F35),I35>=0,ISNUMBER(H35),H35>=0),"纳入","待核实"))
I36: =IF(OR(A36<> '控制台'!B4,B36<> '控制台'!B5,F36=""),"",DATE(VALUE(LEFT('控制台'!B5,4)),VALUE(RIGHT('控制台'!B5,2))+1,1)-1-F36) | J36: =IF(OR(A36<> '控制台'!B4,B36<> '控制台'!B5,G36=""),"",MAX(0,DATE(VALUE(LEFT('控制台'!B5,4)),VALUE(RIGHT('控制台'!B5,2))+1,1)-1-G36)) | K36: =IF(A36="","",IF(AND(AND('控制台'!B4<>"",'控制台'!B5<>"",'控制台'!B4='刷新信息'!B6,'控制台'!B5='刷新信息'!B8),A36='控制台'!B4,B36='控制台'!B5,OR(C36="应收",C36="应付"),COUNTIFS('往来余额'!A5:A6000,C36,'往来余额'!B5:B6000,D36)=1,E36<>"",COUNTIFS(A$5:A$504,A36,B$5:B$504,B36,C$5:C$504,C36,D$5:D$504,D36,E$5:E$504,E36)=1,ISNUMBER(F36),I36>=0,ISNUMBER(H36),H36>=0),"纳入","待核实"))
I37: =IF(OR(A37<> '控制台'!B4,B37<> '控制台'!B5,F37=""),"",DATE(VALUE(LEFT('控制台'!B5,4)),VALUE(RIGHT('控制台'!B5,2))+1,1)-1-F37) | J37: =IF(OR(A37<> '控制台'!B4,B37<> '控制台'!B5,G37=""),"",MAX(0,DATE(VALUE(LEFT('控制台'!B5,4)),VALUE(RIGHT('控制台'!B5,2))+1,1)-1-G37)) | K37: =IF(A37="","",IF(AND(AND('控制台'!B4<>"",'控制台'!B5<>"",'控制台'!B4='刷新信息'!B6,'控制台'!B5='刷新信息'!B8),A37='控制台'!B4,B37='控制台'!B5,OR(C37="应收",C37="应付"),COUNTIFS('往来余额'!A5:A6000,C37,'往来余额'!B5:B6000,D37)=1,E37<>"",COUNTIFS(A$5:A$504,A37,B$5:B$504,B37,C$5:C$504,C37,D$5:D$504,D37,E$5:E$504,E37)=1,ISNUMBER(F37),I37>=0,ISNUMBER(H37),H37>=0),"纳入","待核实"))
I38: =IF(OR(A38<> '控制台'!B4,B38<> '控制台'!B5,F38=""),"",DATE(VALUE(LEFT('控制台'!B5,4)),VALUE(RIGHT('控制台'!B5,2))+1,1)-1-F38) | J38: =IF(OR(A38<> '控制台'!B4,B38<> '控制台'!B5,G38=""),"",MAX(0,DATE(VALUE(LEFT('控制台'!B5,4)),VALUE(RIGHT('控制台'!B5,2))+1,1)-1-G38)) | K38: =IF(A38="","",IF(AND(AND('控制台'!B4<>"",'控制台'!B5<>"",'控制台'!B4='刷新信息'!B6,'控制台'!B5='刷新信息'!B8),A38='控制台'!B4,B38='控制台'!B5,OR(C38="应收",C38="应付"),COUNTIFS('往来余额'!A5:A6000,C38,'往来余额'!B5:B6000,D38)=1,E38<>"",COUNTIFS(A$5:A$504,A38,B$5:B$504,B38,C$5:C$504,C38,D$5:D$504,D38,E$5:E$504,E38)=1,ISNUMBER(F38),I38>=0,ISNUMBER(H38),H38>=0),"纳入","待核实"))
I39: =IF(OR(A39<> '控制台'!B4,B39<> '控制台'!B5,F39=""),"",DATE(VALUE(LEFT('控制台'!B5,4)),VALUE(RIGHT('控制台'!B5,2))+1,1)-1-F39) | J39: =IF(OR(A39<> '控制台'!B4,B39<> '控制台'!B5,G39=""),"",MAX(0,DATE(VALUE(LEFT('控制台'!B5,4)),VALUE(RIGHT('控制台'!B5,2))+1,1)-1-G39)) | K39: =IF(A39="","",IF(AND(AND('控制台'!B4<>"",'控制台'!B5<>"",'控制台'!B4='刷新信息'!B6,'控制台'!B5='刷新信息'!B8),A39='控制台'!B4,B39='控制台'!B5,OR(C39="应收",C39="应付"),COUNTIFS('往来余额'!A5:A6000,C39,'往来余额'!B5:B6000,D39)=1,E39<>"",COUNTIFS(A$5:A$504,A39,B$5:B$504,B39,C$5:C$504,C39,D$5:D$504,D39,E$5:E$504,E39)=1,ISNUMBER(F39),I39>=0,ISNUMBER(H39),H39>=0),"纳入","待核实"))
I40: =IF(OR(A40<> '控制台'!B4,B40<> '控制台'!B5,F40=""),"",DATE(VALUE(LEFT('控制台'!B5,4)),VALUE(RIGHT('控制台'!B5,2))+1,1)-1-F40) | J40: =IF(OR(A40<> '控制台'!B4,B40<> '控制台'!B5,G40=""),"",MAX(0,DATE(VALUE(LEFT('控制台'!B5,4)),VALUE(RIGHT('控制台'!B5,2))+1,1)-1-G40)) | K40: =IF(A40="","",IF(AND(AND('控制台'!B4<>"",'控制台'!B5<>"",'控制台'!B4='刷新信息'!B6,'控制台'!B5='刷新信息'!B8),A40='控制台'!B4,B40='控制台'!B5,OR(C40="应收",C40="应付"),COUNTIFS('往来余额'!A5:A6000,C40,'往来余额'!B5:B6000,D40)=1,E40<>"",COUNTIFS(A$5:A$504,A40,B$5:B$504,B40,C$5:C$504,C40,D$5:D$504,D40,E$5:E$504,E40)=1,ISNUMBER(F40),I40>=0,ISNUMBER(H40),H40>=0),"纳入","待核实"))
I41: =IF(OR(A41<> '控制台'!B4,B41<> '控制台'!B5,F41=""),"",DATE(VALUE(LEFT('控制台'!B5,4)),VALUE(RIGHT('控制台'!B5,2))+1,1)-1-F41) | J41: =IF(OR(A41<> '控制台'!B4,B41<> '控制台'!B5,G41=""),"",MAX(0,DATE(VALUE(LEFT('控制台'!B5,4)),VALUE(RIGHT('控制台'!B5,2))+1,1)-1-G41)) | K41: =IF(A41="","",IF(AND(AND('控制台'!B4<>"",'控制台'!B5<>"",'控制台'!B4='刷新信息'!B6,'控制台'!B5='刷新信息'!B8),A41='控制台'!B4,B41='控制台'!B5,OR(C41="应收",C41="应付"),COUNTIFS('往来余额'!A5:A6000,C41,'往来余额'!B5:B6000,D41)=1,E41<>"",COUNTIFS(A$5:A$504,A41,B$5:B$504,B41,C$5:C$504,C41,D$5:D$504,D41,E$5:E$504,E41)=1,ISNUMBER(F41),I41>=0,ISNUMBER(H41),H41>=0),"纳入","待核实"))
...

Sheet 账龄统计
A1: 账龄统计
A2: 按发生日计算账龄；逾期按到期日计算。未分配金额不推断账龄。
A4: 类型 | B4: 往来净余额 | C4: 已分配单据 | D4: 未分配净额 | E4: 0–30天 | F4: 31–60天 | G4: 61–90天 | H4: 91–180天 | I4: 181–365天 | J4: 365天以上 | K4: 逾期金额
A5: 应收 | B5: =IF(AND('控制台'!B4<>"",'控制台'!B5<>"",'控制台'!B4='刷新信息'!B6,'控制台'!B5='刷新信息'!B8),'经营统计'!B11,"") | C5: =IF(AND('控制台'!B4<>"",'控制台'!B5<>"",'控制台'!B4='刷新信息'!B6,'控制台'!B5='刷新信息'!B8),SUMIFS('账龄输入'!H5:H504,'账龄输入'!C5:C504,A5,'账龄输入'!K5:K504,"纳入"),"") | D5: =IF(AND('控制台'!B4<>"",'控制台'!B5<>"",'控制台'!B4='刷新信息'!B6,'控制台'!B5='刷新信息'!B8),B5-C5,"") | E5: =IF(AND('控制台'!B4<>"",'控制台'!B5<>"",'控制台'!B4='刷新信息'!B6,'控制台'!B5='刷新信息'!B8),SUMIFS('账龄输入'!H5:H504,'账龄输入'!C5:C504,A5,'账龄输入'!K5:K504,"纳入",'账龄输入'!I5:I504,">=0",'账龄输入'!I5:I504,"<=30"),"") | F5: =IF(AND('控制台'!B4<>"",'控制台'!B5<>"",'控制台'!B4='刷新信息'!B6,'控制台'!B5='刷新信息'!B8),SUMIFS('账龄输入'!H5:H504,'账龄输入'!C5:C504,A5,'账龄输入'!K5:K504,"纳入",'账龄输入'!I5:I504,">=31",'账龄输入'!I5:I504,"<=60"),"") | G5: =IF(AND('控制台'!B4<>"",'控制台'!B5<>"",'控制台'!B4='刷新信息'!B6,'控制台'!B5='刷新信息'!B8),SUMIFS('账龄输入'!H5:H504,'账龄输入'!C5:C504,A5,'账龄输入'!K5:K504,"纳入",'账龄输入'!I5:I504,">=61",'账龄输入'!I5:I504,"<=90"),"") | H5: =IF(AND('控制台'!B4<>"",'控制台'!B5<>"",'控制台'!B4='刷新信息'!B6,'控制台'!B5='刷新信息'!B8),SUMIFS('账龄输入'!H5:H504,'账龄输入'!C5:C504,A5,'账龄输入'!K5:K504,"纳入",'账龄输入'!I5:I504,">=91",'账龄输入'!I5:I504,"<=180"),"") | I5: =IF(AND('控制台'!B4<>"",'控制台'!B5<>"",'控制台'!B4='刷新信息'!B6,'控制台'!B5='刷新信息'!B8),SUMIFS('账龄输入'!H5:H504,'账龄输入'!C5:C504,A5,'账龄输入'!K5:K504,"纳入",'账龄输入'!I5:I504,">=181",'账龄输入'!I5:I504,"<=365"),"") | J5: =IF(AND('控制台'!B4<>"",'控制台'!B5<>"",'控制台'!B4='刷新信息'!B6,'控制台'!B5='刷新信息'!B8),SUMIFS('账龄输入'!H5:H504,'账龄输入'!C5:C504,A5,'账龄输入'!K5:K504,"纳入",'账龄输入'!I5:I504,">=366",'账龄输入'!I5:I504,"<=999999"),"") | K5: =IF(AND('控制台'!B4<>"",'控制台'!B5<>"",'控制台'!B4='刷新信息'!B6,'控制台'!B5='刷新信息'!B8),SUMIFS('账龄输入'!H5:H504,'账龄输入'!C5:C504,A5,'账龄输入'!K5:K504,"纳入",'账龄输入'!J5:J504,">0"),"")
A6: 应付 | B6: =IF(AND('控制台'!B4<>"",'控制台'!B5<>"",'控制台'!B4='刷新信息'!B6,'控制台'!B5='刷新信息'!B8),'经营统计'!B12,"") | C6: =IF(AND('控制台'!B4<>"",'控制台'!B5<>"",'控制台'!B4='刷新信息'!B6,'控制台'!B5='刷新信息'!B8),SUMIFS('账龄输入'!H5:H504,'账龄输入'!C5:C504,A6,'账龄输入'!K5:K504,"纳入"),"") | D6: =IF(AND('控制台'!B4<>"",'控制台'!B5<>"",'控制台'!B4='刷新信息'!B6,'控制台'!B5='刷新信息'!B8),B6-C6,"") | E6: =IF(AND('控制台'!B4<>"",'控制台'!B5<>"",'控制台'!B4='刷新信息'!B6,'控制台'!B5='刷新信息'!B8),SUMIFS('账龄输入'!H5:H504,'账龄输入'!C5:C504,A6,'账龄输入'!K5:K504,"纳入",'账龄输入'!I5:I504,">=0",'账龄输入'!I5:I504,"<=30"),"") | F6: =IF(AND('控制台'!B4<>"",'控制台'!B5<>"",'控制台'!B4='刷新信息'!B6,'控制台'!B5='刷新信息'!B8),SUMIFS('账龄输入'!H5:H504,'账龄输入'!C5:C504,A6,'账龄输入'!K5:K504,"纳入",'账龄输入'!I5:I504,">=31",'账龄输入'!I5:I504,"<=60"),"") | G6: =IF(AND('控制台'!B4<>"",'控制台'!B5<>"",'控制台'!B4='刷新信息'!B6,'控制台'!B5='刷新信息'!B8),SUMIFS('账龄输入'!H5:H504,'账龄输入'!C5:C504,A6,'账龄输入'!K5:K504,"纳入",'账龄输入'!I5:I504,">=61",'账龄输入'!I5:I504,"<=90"),"") | H6: =IF(AND('控制台'!B4<>"",'控制台'!B5<>"",'控制台'!B4='刷新信息'!B6,'控制台'!B5='刷新信息'!B8),SUMIFS('账龄输入'!H5:H504,'账龄输入'!C5:C504,A6,'账龄输入'!K5:K504,"纳入",'账龄输入'!I5:I504,">=91",'账龄输入'!I5:I504,"<=180"),"") | I6: =IF(AND('控制台'!B4<>"",'控制台'!B5<>"",'控制台'!B4='刷新信息'!B6,'控制台'!B5='刷新信息'!B8),SUMIFS('账龄输入'!H5:H504,'账龄输入'!C5:C504,A6,'账龄输入'!K5:K504,"纳入",'账龄输入'!I5:I504,">=181",'账龄输入'!I5:I504,"<=365"),"") | J6: =IF(AND('控制台'!B4<>"",'控制台'!B5<>"",'控制台'!B4='刷新信息'!B6,'控制台'!B5='刷新信息'!B8),SUMIFS('账龄输入'!H5:H504,'账龄输入'!C5:C504,A6,'账龄输入'!K5:K504,"纳入",'账龄输入'!I5:I504,">=366",'账龄输入'!I5:I504,"<=999999"),"") | K6: =IF(AND('控制台'!B4<>"",'控制台'!B5<>"",'控制台'!B4='刷新信息'!B6,'控制台'!B5='刷新信息'!B8),SUMIFS('账龄输入'!H5:H504,'账龄输入'!C5:C504,A6,'账龄输入'!K5:K504,"纳入",'账龄输入'!J5:J504,">0"),"")
A9: 未分配净额包括未录入单据及预收预付抵减；不等于已核销差异，也不等于逾期金额。

Sheet 刷新信息
A1: 刷新信息
A2: 尚未读取数据；请先配置刷新连接
A4: 字段 | B4: 值
A5: schema | B5: 1
A6: company
A7: company_name
A8: month
A9: refreshed_at_utc

Sheet 公司列表
A1: 可选公司
A2: 尚未读取数据；请先配置刷新连接
A4: 公司编号 | B4: 公司名称

Sheet 利润表
A1: 利润表
A2: 尚未读取数据；请先配置刷新连接
A4: 项目编码 | B4: 项目 | C4: 本月金额 | D4: 本年累计 | E4: 上年累计 | F4: 统计分类

Sheet 资产负债表
A1: 资产负债表
A2: 尚未读取数据；请先配置刷新连接
A4: 资产 | B4: 期末余额 | C4: 年初余额 | D4: 负债与权益 | E4: 期末余额 | F4: 年初余额

Sheet 现金流量表
A1: 现金流量表
A2: 尚未读取数据；请先配置刷新连接
A4: 区块 | B4: 项目编码 | C4: 项目 | D4: balance | E4: curBalance | F4: preBalance

Sheet 科目余额
A1: 科目余额
A2: 尚未读取数据；请先配置刷新连接
A4: 科目编码 | B4: 科目 | C4: 期初借方 | D4: 期初贷方 | E4: 本期借方 | F4: 本期贷方 | G4: 期末借方 | H4: 期末贷方 | I4: 末级

Sheet 凭证明细
A1: 凭证明细
A2: 尚未读取数据；请先配置刷新连接
A4: 凭证ID | B4: 分录序号 | C4: 日期 | D4: 凭证号 | E4: 科目编码 | F4: 科目名称 | G4: 辅助项目 | H4: 摘要 | I4: 借方 | J4: 贷方 | K4: 币种 | L4: 原币金额 | M4: 收支类型

Sheet 出纳账
A1: 出纳账（总账口径）
A2: 尚未读取数据；请先配置刷新连接
A4: 凭证ID | B4: 分录序号 | C4: 日期 | D4: 凭证号 | E4: 科目编码 | F4: 科目名称 | G4: 辅助项目 | H4: 摘要 | I4: 借方 | J4: 贷方 | K4: 币种 | L4: 原币金额 | M4: 收支类型

Sheet 往来余额
A1: 往来余额
A2: 尚未读取数据；请先配置刷新连接
A4: 类型 | B4: 核算项目ID组合 | C4: 编码 | D4: 名称 | E4: 期初借方 | F4: 期初贷方 | G4: 本期借方 | H4: 本期贷方 | I4: 期末借方 | J4: 期末贷方

Sheet 月度趋势
A1: 利润月度明细
A2: 尚未读取数据；请先配置刷新连接
A4: 月份 | B4: 项目编码 | C4: 项目 | D4: 本月金额 | E4: 统计分类

Sheet 使用说明
A1: 使用说明
A2: 一次性安装按钮后，日常只需选择公司、月份并刷新。
A4: 事项 | B4: 说明
A5: 连接 | B5: Windows 通过 SSH 转发连接 Linux 的只读服务；账无忧会话只保存在后台。
A6: 首次安装 | B6: 运行 scripts/finance/install-excel.ps1，将此 .xlsx 转为 .xlsm 并加入刷新按钮。
A7: 输入保护 | B7: 刷新只替换原始数据表；预算输入、账龄输入及其公式不会被覆盖。
A8: 容量 | B8: 每张接口表最多 6000 行；预算输入 200 行、账龄输入 500 行。超限需要扩展公式。
A9: 账龄 | B9: 当前未接入单据核销与到期日接口；人工补充未核销单据后计算，不伪造自动账龄。
A10: 出纳 | B10: 总账1001/1002科目；仅现金银行科目之间的凭证识别为内部划转。复合凭证仍需复核。
A11: 利润口径 | B11: 利润表本月balance、本年累计curBalance、上年累计preBalance；以账无忧报表为准。
A12: 现金流字段 | B12: 保留原接口字段名，字段期间口径需对照账套现金流量表；不将未知字段重命名。
A13: 异常 | B13: 失败时保留旧数据；更换选择但未刷新时统计页留空；原系统校验信息在刷新信息中。
A14: 参考结构 | B14: https://www.vertex42.com/ExcelTemplates/financial-statements.html
A15: 参考范围 | B15: https://www.smartsheet.com/content/free-business-templates
